Workbook

Sheet Inputs
A1: Option pricing: SPY, valuation date 2024-12-31
A3: Spot S0 (SPY close 2024-12-31) | B3: 574.78802
A4: Strike K (nearest 5 to spot) | B4: 575
A5: Maturity T (years) | B5: 0.25
A6: Risk-free rate r (3M T-bill, FRED DGS3MO) | B6: 0.0437
A7: Dividend yield q (assumed) | B7: 0.012
A8: Volatility sigma (annualized 2024 realized) | B8: =STDEV(Data!D3:D253)*SQRT(252) -> 0.12593185
A9: Barrier H (up-and-out) | B9: 603.75
A10: Binomial steps | B10: 20
A11: Monte Carlo steps | B11: 63
A13: S0, K, T, r, q, sigma, H are in B3:B9. The dividend yield and strike are illustrative assumptions, not a quoted contract.

Sheet MC_Results
A1: Monte Carlo results (500 antithetic paths) | B1: Price | C1: Std error | D1: Black-Scholes / note
A3: European call | B3: =EXP(-Inputs!$B$6*Inputs!$B$5)*AVERAGE(MC_Paths!BP5:BP504) -> 15.715462 | C3: =EXP(-Inputs!$B$6*Inputs!$B$5)*STDEV(MC_Paths!BP5:BP504)/SQRT(500) -> 1.007298 | D3: =BlackScholes!B5 -> 16.598796
A4: European put | B4: =EXP(-Inputs!$B$6*Inputs!$B$5)*AVERAGE(MC_Paths!BQ5:BQ504) -> 11.492574 | C4: =EXP(-Inputs!$B$6*Inputs!$B$5)*STDEV(MC_Paths!BQ5:BQ504)/SQRT(500) -> 0.81562735 | D4: =BlackScholes!B6 -> 12.284867
A5: Asian call (arithmetic average) | B5: =EXP(-Inputs!$B$6*Inputs!$B$5)*AVERAGE(MC_Paths!BR5:BR504) -> 9.446974 | C5: =EXP(-Inputs!$B$6*Inputs!$B$5)*STDEV(MC_Paths!BR5:BR504)/SQRT(500) -> 0.58779501 | D5: No closed form here
A6: Up-and-out call (barrier H) | B6: =EXP(-Inputs!$B$6*Inputs!$B$5)*AVERAGE(MC_Paths!BS5:BS504) -> 1.8064927 | C6: =EXP(-Inputs!$B$6*Inputs!$B$5)*STDEV(MC_Paths!BS5:BS504)/SQRT(500) -> 0.22602485 | D6: No closed form here
A9: Antithetic pairs are correlated, so the standard error above is conservative (it treats all 500 paths as independent).

Sheet Data
A1: Date | B1: SPY | C1: JPM | D1: SPY log ret | E1: JPM log ret
A2: 45293 | B2: 457.6727 | C2: 162.27827
A3: 45294 | B3: 453.93503 | C3: 161.57101 | D3: =LN(B3/B2) -> -0.0082002197 | E3: =LN(C3/C2) -> -0.004367842
A4: 45295 | B4: 452.47287 | C4: 162.6432 | D4: =LN(B4/B3) -> -0.0032262726 | E4: =LN(C4/C3) -> 0.0066141038
A5: 45296 | B5: 453.09259 | C5: 163.45923 | D5: =LN(B5/B4) -> 0.001368693 | E5: =LN(C5/C4) -> 0.0050047249
A6: 45299 | B6: 459.56094 | C6: 163.22203 | D6: =LN(B6/B5) -> 0.014175065 | E6: =LN(C6/C5) -> -0.0014521673
A7: 45300 | B7: 458.86371 | C7: 161.93155 | D7: =LN(B7/B6) -> -0.0015183287 | E7: =LN(C7/C6) -> -0.0079377157
A8: 45301 | B8: 461.45877 | C8: 162.27315 | D8: =LN(B8/B7) -> 0.0056394779 | E8: =LN(C8/C7) -> 0.0021073022
A9: 45302 | B9: 461.25552 | C9: 161.59 | D9: =LN(B9/B8) -> -0.00044054173 | E9: =LN(C9/C8) -> -0.0042187712
A10: 45303 | B10: 461.57498 | C10: 160.40392 | D10: =LN(B10/B9) -> 0.00069234387 | E10: =LN(C10/C9) -> -0.0073671349
A11: 45307 | B11: 459.88049 | C11: 159.39816 | D11: =LN(B11/B10) -> -0.0036778564 | E11: =LN(C11/C10) -> -0.0062898646
A12: 45308 | B12: 457.32413 | C12: 158.54417 | D12: =LN(B12/B11) -> -0.0055742689 | E12: =LN(C12/C11) -> -0.0053719848
A13: 45309 | B13: 461.39099 | C13: 158.85728 | D13: =LN(B13/B12) -> 0.0088534313 | E13: =LN(C13/C12) -> 0.0019729617
A14: 45310 | B14: 467.14282 | C14: 161.59949 | D14: =LN(B14/B13) -> 0.01238922 | E14: =LN(C14/C13) -> 0.017114756
... A253: 45657 | B253: 574.78802 | C253: 231.45416 | D253: =LN(B253/B252) -> -0.003644493 | E253: =LN(C253/C252) -> 0.0016283065

Sheet BlackScholes
A1: Black-Scholes-Merton (continuous dividend yield)
A3: d1 | B3: =(LN(Inputs!B3/Inputs!B4)+(Inputs!B6-Inputs!B7+0.5*Inputs!B8^2)*Inputs!B5)/(Inputs!B8*SQRT(Inputs!B5)) -> 0.15148882
A4: d2 | B4: =B3-Inputs!B8*SQRT(Inputs!B5) -> 0.088522891
A5: Call | B5: =Inputs!B3*EXP(-Inputs!B7*Inputs!B5)*NORMSDIST(B3)-Inputs!B4*EXP(-Inputs!B6*Inputs!B5)*NORMSDIST(B4) -> 16.598796
A6: Put | B6: =Inputs!B4*EXP(-Inputs!B6*Inputs!B5)*NORMSDIST(-B4)-Inputs!B3*EXP(-Inputs!B7*Inputs!B5)*NORMSDIST(-B3) -> 12.284867
A7: Put-call parity error | B7: =B5-B6-(Inputs!B3*EXP(-Inputs!B7*Inputs!B5)-Inputs!B4*EXP(-Inputs!B6*Inputs!B5)) -> 2.8421709e-14
A8: Call delta | B8: =EXP(-Inputs!B7*Inputs!B5)*NORMSDIST(B3) -> 0.55852684
A9: Gamma | B9: =EXP(-Inputs!B7*Inputs!B5)*NORMDIST(B3,0,1,FALSE())/(Inputs!B3*Inputs!B8*SQRT(Inputs!B5)) -> 0.010864521
A10: Vega (per 1.00 vol) | B10: =Inputs!B3*EXP(-Inputs!B7*Inputs!B5)*NORMDIST(B3,0,1,FALSE())*SQRT(Inputs!B5) -> 113.00603

Sheet Binomial
A1: Cox-Ross-Rubinstein tree, 20 steps: European call and American put
A2: dt | B2: =Inputs!B5/Inputs!B10 -> 0.0125 | C2: u | D2: =EXP(Inputs!B8*SQRT(B2)) -> 1.0141792 | E2: d | F2: =1/D2 -> 0.98601905 | G2: p | H2: =(EXP((Inputs!B6-Inputs!B7)*B2)-F2)/(D2-F2) -> 0.51055425 | I2: disc | J2: =EXP(-Inputs!B6*B2) -> 0.9994539 | X2: Binomial European call | Y2: =B28 -> 16.437634
A3: Stock price tree | X3: Black-Scholes call | Y3: =BlackScholes!B5 -> 16.598796
B4: 0 | C4: 1 | D4: 2 | E4: 3 | F4: 4 | G4: 5 | H4: 6 | I4: 7 | J4: 8 | K4: 9 | L4: 10 | M4: 11 | N4: 12 | O4: 13 | P4: 14 | Q4: 15 | R4: 16 | S4: 17 | T4: 18 | U4: 19 | V4: 20 | X4: American put (tree) | Y4: =B51 -> 12.599839
B5: =Inputs!$B$3*$D$2^(0-0)*$F$2^0 -> 574.78802 | C5: =Inputs!$B$3*$D$2^(1-0)*$F$2^0 -> 582.93806 | D5: =Inputs!$B$3*$D$2^(2-0)*$F$2^0 -> 591.20365 | E5: =Inputs!$B$3*$D$2^(3-0)*$F$2^0 -> 599.58644 | F5: =Inputs!$B$3*$D$2^(4-0)*$F$2^0 -> 608.08809 | G5: =Inputs!$B$3*$D$2^(5-0)*$F$2^0 -> 616.71029 | H5: =Inputs!$B$3*$D$2^(6-0)*$F$2^0 -> 625.45474 | I5: =Inputs!$B$3*$D$2^(7-0)*$F$2^0 -> 634.32319 | J5: =Inputs!$B$3*$D$2^(8-0)*$F$2^0 -> 643.31738 | K5: =Inputs!$B$3*$D$2^(9-0)*$F$2^0 -> 652.4391 | L5: =Inputs!$B$3*$D$2^(10-0)*$F$2^0 -> 661.69016 | M5: =Inputs!$B$3*$D$2^(11-0)*$F$2^0 -> 671.07239 | N5: =Inputs!$B$3*$D$2^(12-0)*$F$2^0 -> 680.58766 | O5: =Inputs!$B$3*$D$2^(13-0)*$F$2^0 -> 690.23784 | P5: =Inputs!$B$3*$D$2^(14-0)*$F$2^0 -> 700.02486 | Q5: =Inputs!$B$3*$D$2^(15-0)*$F$2^0 -> 709.95065 | R5: =Inputs!$B$3*$D$2^(16-0)*$F$2^0 -> 720.01717 | S5: =Inputs!$B$3*$D$2^(17-0)*$F$2^0 -> 730.22644 | T5: =Inputs!$B$3*$D$2^(18-0)*$F$2^0 -> 740.58046 | U5: =Inputs!$B$3*$D$2^(19-0)*$F$2^0 -> 751.08129 | V5: =Inputs!$B$3*$D$2^(20-0)*$F$2^0 -> 761.73102 | X5: European put (Black-Scholes) | Y5: =BlackScholes!B6 -> 12.284867
C6: =Inputs!$B$3*$D$2^(1-1)*$F$2^1 -> 566.75194 | D6: =Inputs!$B$3*$D$2^(2-1)*$F$2^1 -> 574.78802 | E6: =Inputs!$B$3*$D$2^(3-1)*$F$2^1 -> 582.93806 | F6: =Inputs!$B$3*$D$2^(4-1)*$F$2^1 -> 591.20365 | G6: =Inputs!$B$3*$D$2^(5-1)*$F$2^1 -> 599.58644 | H6: =Inputs!$B$3*$D$2^(6-1)*$F$2^1 -> 608.08809 | I6: =Inputs!$B$3*$D$2^(7-1)*$F$2^1 -> 616.71029 | J6: =Inputs!$B$3*$D$2^(8-1)*$F$2^1 -> 625.45474 | K6: =Inputs!$B$3*$D$2^(9-1)*$F$2^1 -> 634.32319 | L6: =Inputs!$B$3*$D$2^(10-1)*$F$2^1 -> 643.31738 | M6: =Inputs!$B$3*$D$2^(11-1)*$F$2^1 -> 652.4391 | N6: =Inputs!$B$3*$D$2^(12-1)*$F$2^1 -> 661.69016 | O6: =Inputs!$B$3*$D$2^(13-1)*$F$2^1 -> 671.07239 | P6: =Inputs!$B$3*$D$2^(14-1)*$F$2^1 -> 680.58766 | Q6: =Inputs!$B$3*$D$2^(15-1)*$F$2^1 -> 690.23784 | R6: =Inputs!$B$3*$D$2^(16-1)*$F$2^1 -> 700.02486 | S6: =Inputs!$B$3*$D$2^(17-1)*$F$2^1 -> 709.95065 | T6: =Inputs!$B$3*$D$2^(18-1)*$F$2^1 -> 720.01717 | U6: =Inputs!$B$3*$D$2^(19-1)*$F$2^1 -> 730.22644 | V6: =Inputs!$B$3*$D$2^(20-1)*$F$2^1 -> 740.58046 | X6: Early-exercise premium | Y6: =Y4-Y5 -> 0.31497218
D7: =Inputs!$B$3*$D$2^(2-2)*$F$2^2 -> 558.82821 | E7: =Inputs!$B$3*$D$2^(3-2)*$F$2^2 -> 566.75194 | F7: =Inputs!$B$3*$D$2^(4-2)*$F$2^2 -> 574.78802 | G7: =Inputs!$B$3*$D$2^(5-2)*$F$2^2 -> 582.93806 | H7: =Inputs!$B$3*$D$2^(6-2)*$F$2^2 -> 591.20365 | I7: =Inputs!$B$3*$D$2^(7-2)*$F$2^2 -> 599.58644 | J7: =Inputs!$B$3*$D$2^(8-2)*$F$2^2 -> 608.08809 | K7: =Inputs!$B$3*$D$2^(9-2)*$F$2^2 -> 616.71029 | L7: =Inputs!$B$3*$D$2^(10-2)*$F$2^2 -> 625.45474 | M7: =Inputs!$B$3*$D$2^(11-2)*$F$2^2 -> 634.32319 | N7: =Inputs!$B$3*$D$2^(12-2)*$F$2^2 -> 643.31738 | O7: =Inputs!$B$3*$D$2^(13-2)*$F$2^2 -> 652.4391 | P7: =Inputs!$B$3*$D$2^(14-2)*$F$2^2 -> 661.69016 | Q7: =Inputs!$B$3*$D$2^(15-2)*$F$2^2 -> 671.07239 | R7: =Inputs!$B$3*$D$2^(16-2)*$F$2^2 -> 680.58766 | S7: =Inputs!$B$3*$D$2^(17-2)*$F$2^2 -> 690.23784 | T7: =Inputs!$B$3*$D$2^(18-2)*$F$2^2 -> 700.02486 | U7: =Inputs!$B$3*$D$2^(19-2)*$F$2^2 -> 709.95065 | V7: =Inputs!$B$3*$D$2^(20-2)*$F$2^2 -> 720.01717
E8: =Inputs!$B$3*$D$2^(3-3)*$F$2^3 -> 551.01525 | F8: =Inputs!$B$3*$D$2^(4-3)*$F$2^3 -> 558.82821 | G8: =Inputs!$B$3*$D$2^(5-3)*$F$2^3 -> 566.75194 | H8: =Inputs!$B$3*$D$2^(6-3)*$F$2^3 -> 574.78802 | I8: =Inputs!$B$3*$D$2^(7-3)*$F$2^3 -> 582.93806 | J8: =Inputs!$B$3*$D$2^(8-3)*$F$2^3 -> 591.20365 | K8: =Inputs!$B$3*$D$2^(9-3)*$F$2^3 -> 599.58644 | L8: =Inputs!$B$3*$D$2^(10-3)*$F$2^3 -> 608.08809 | M8: =Inputs!$B$3*$D$2^(11-3)*$F$2^3 -> 616.71029 | N8: =Inputs!$B$3*$D$2^(12-3)*$F$2^3 -> 625.45474 | O8: =Inputs!$B$3*$D$2^(13-3)*$F$2^3 -> 634.32319 | P8: =Inputs!$B$3*$D$2^(14-3)*$F$2^3 -> 643.31738 | Q8: =Inputs!$B$3*$D$2^(15-3)*$F$2^3 -> 652.4391 | R8: =Inputs!$B$3*$D$2^(16-3)*$F$2^3 -> 661.69016 | S8: =Inputs!$B$3*$D$2^(17-3)*$F$2^3 -> 671.07239 | T8: =Inputs!$B$3*$D$2^(18-3)*$F$2^3 -> 680.58766 | U8: =Inputs!$B$3*$D$2^(19-3)*$F$2^3 -> 690.23784 | V8: =Inputs!$B$3*$D$2^(20-3)*$F$2^3 -> 700.02486
F9: =Inputs!$B$3*$D$2^(4-4)*$F$2^4 -> 543.31153 | G9: =Inputs!$B$3*$D$2^(5-4)*$F$2^4 -> 551.01525 | H9: =Inputs!$B$3*$D$2^(6-4)*$F$2^4 -> 558.82821 | I9: =Inputs!$B$3*$D$2^(7-4)*$F$2^4 -> 566.75194 | J9: =Inputs!$B$3*$D$2^(8-4)*$F$2^4 -> 574.78802 | K9: =Inputs!$B$3*$D$2^(9-4)*$F$2^4 -> 582.93806 | L9: =Inputs!$B$3*$D$2^(10-4)*$F$2^4 -> 591.20365 | M9: =Inputs!$B$3*$D$2^(11-4)*$F$2^4 -> 599.58644 | N9: =Inputs!$B$3*$D$2^(12-4)*$F$2^4 -> 608.08809 | O9: =Inputs!$B$3*$D$2^(13-4)*$F$2^4 -> 616.71029 | P9: =Inputs!$B$3*$D$2^(14-4)*$F$2^4 -> 625.45474 | Q9: =Inputs!$B$3*$D$2^(15-4)*$F$2^4 -> 634.32319 | R9: =Inputs!$B$3*$D$2^(16-4)*$F$2^4 -> 643.31738 | S9: =Inputs!$B$3*$D$2^(17-4)*$F$2^4 -> 652.4391 | T9: =Inputs!$B$3*$D$2^(18-4)*$F$2^4 -> 661.69016 | U9: =Inputs!$B$3*$D$2^(19-4)*$F$2^4 -> 671.07239 | V9: =Inputs!$B$3*$D$2^(20-4)*$F$2^4 -> 680.58766
G10: =Inputs!$B$3*$D$2^(5-5)*$F$2^5 -> 535.71552 | H10: =Inputs!$B$3*$D$2^(6-5)*$F$2^5 -> 543.31153 | I10: =Inputs!$B$3*$D$2^(7-5)*$F$2^5 -> 551.01525 | J10: =Inputs!$B$3*$D$2^(8-5)*$F$2^5 -> 558.82821 | K10: =Inputs!$B$3*$D$2^(9-5)*$F$2^5 -> 566.75194 | L10: =Inputs!$B$3*$D$2^(10-5)*$F$2^5 -> 574.78802 | M10: =Inputs!$B$3*$D$2^(11-5)*$F$2^5 -> 582.93806 | N10: =Inputs!$B$3*$D$2^(12-5)*$F$2^5 -> 591.20365 | O10: =Inputs!$B$3*$D$2^(13-5)*$F$2^5 -> 599.58644 | P10: =Inputs!$B$3*$D$2^(14-5)*$F$2^5 -> 608.08809 | Q10: =Inputs!$B$3*$D$2^(15-5)*$F$2^5 -> 616.71029 | R10: =Inputs!$B$3*$D$2^(16-5)*$F$2^5 -> 625.45474 | S10: =Inputs!$B$3*$D$2^(17-5)*$F$2^5 -> 634.32319 | T10: =Inputs!$B$3*$D$2^(18-5)*$F$2^5 -> 643.31738 | U10: =Inputs!$B$3*$D$2^(19-5)*$F$2^5 -> 652.4391 | V10: =Inputs!$B$3*$D$2^(20-5)*$F$2^5 -> 661.69016
H11: =Inputs!$B$3*$D$2^(6-6)*$F$2^6 -> 528.22571 | I11: =Inputs!$B$3*$D$2^(7-6)*$F$2^6 -> 535.71552 | J11: =Inputs!$B$3*$D$2^(8-6)*$F$2^6 -> 543.31153 | K11: =Inputs!$B$3*$D$2^(9-6)*$F$2^6 -> 551.01525 | L11: =Inputs!$B$3*$D$2^(10-6)*$F$2^6 -> 558.82821 | M11: =Inputs!$B$3*$D$2^(11-6)*$F$2^6 -> 566.75194 | N11: =Inputs!$B$3*$D$2^(12-6)*$F$2^6 -> 574.78802 | O11: =Inputs!$B$3*$D$2^(13-6)*$F$2^6 -> 582.93806 | P11: =Inputs!$B$3*$D$2^(14-6)*$F$2^6 -> 591.20365 | Q11: =Inputs!$B$3*$D$2^(15-6)*$F$2^6 -> 599.58644 | R11: =Inputs!$B$3*$D$2^(16-6)*$F$2^6 -> 608.08809 | S11: =Inputs!$B$3*$D$2^(17-6)*$F$2^6 -> 616.71029 | T11: =Inputs!$B$3*$D$2^(18-6)*$F$2^6 -> 625.45474 | U11: =Inputs!$B$3*$D$2^(19-6)*$F$2^6 -> 634.32319 | V11: =Inputs!$B$3*$D$2^(20-6)*$F$2^6 -> 643.31738
I12: =Inputs!$B$3*$D$2^(7-7)*$F$2^7 -> 520.84061 | J12: =Inputs!$B$3*$D$2^(8-7)*$F$2^7 -> 528.22571 | K12: =Inputs!$B$3*$D$2^(9-7)*$F$2^7 -> 535.71552 | L12: =Inputs!$B$3*$D$2^(10-7)*$F$2^7 -> 543.31153 | M12: =Inputs!$B$3*$D$2^(11-7)*$F$2^7 -> 551.01525 | N12: =Inputs!$B$3*$D$2^(12-7)*$F$2^7 -> 558.82821 | O12: =Inputs!$B$3*$D$2^(13-7)*$F$2^7 -> 566.75194 | P12: =Inputs!$B$3*$D$2^(14-7)*$F$2^7 -> 574.78802 | Q12: =Inputs!$B$3*$D$2^(15-7)*$F$2^7 -> 582.93806 | R12: =Inputs!$B$3*$D$2^(16-7)*$F$2^7 -> 591.20365 | S12: =Inputs!$B$3*$D$2^(17-7)*$F$2^7 -> 599.58644 | T12: =Inputs!$B$3*$D$2^(18-7)*$F$2^7 -> 608.08809 | U12: =Inputs!$B$3*$D$2^(19-7)*$F$2^7 -> 616.71029 | V12: =Inputs!$B$3*$D$2^(20-7)*$F$2^7 -> 625.45474
J13: =Inputs!$B$3*$D$2^(8-8)*$F$2^8 -> 513.55876 | K13: =Inputs!$B$3*$D$2^(9-8)*$F$2^8 -> 520.84061 | L13: =Inputs!$B$3*$D$2^(10-8)*$F$2^8 -> 528.22571 | M13: =Inputs!$B$3*$D$2^(11-8)*$F$2^8 -> 535.71552 | N13: =Inputs!$B$3*$D$2^(12-8)*$F$2^8 -> 543.31153 | O13: =Inputs!$B$3*$D$2^(13-8)*$F$2^8 -> 551.01525 | P13: =Inputs!$B$3*$D$2^(14-8)*$F$2^8 -> 558.82821 | Q13: =Inputs!$B$3*$D$2^(15-8)*$F$2^8 -> 566.75194 | R13: =Inputs!$B$3*$D$2^(16-8)*$F$2^8 -> 574.78802 | S13: =Inputs!$B$3*$D$2^(17-8)*$F$2^8 -> 582.93806 | T13: =Inputs!$B$3*$D$2^(18-8)*$F$2^8 -> 591.20365 | U13: =Inputs!$B$3*$D$2^(19-8)*$F$2^8 -> 599.58644 | V13: =Inputs!$B$3*$D$2^(20-8)*$F$2^8 -> 608.08809
K14: =Inputs!$B$3*$D$2^(9-9)*$F$2^9 -> 506.37872 | L14: =Inputs!$B$3*$D$2^(10-9)*$F$2^9 -> 513.55876 | M14: =Inputs!$B$3*$D$2^(11-9)*$F$2^9 -> 520.84061 | N14: =Inputs!$B$3*$D$2^(12-9)*$F$2^9 -> 528.22571 | O14: =Inputs!$B$3*$D$2^(13-9)*$F$2^9 -> 535.71552 | P14: =Inputs!$B$3*$D$2^(14-9)*$F$2^9 -> 543.31153 | Q14: =Inputs!$B$3*$D$2^(15-9)*$F$2^9 -> 551.01525 | R14: =Inputs!$B$3*$D$2^(16-9)*$F$2^9 -> 558.82821 | S14: =Inputs!$B$3*$D$2^(17-9)*$F$2^9 -> 566.75194 | T14: =Inputs!$B$3*$D$2^(18-9)*$F$2^9 -> 574.78802 | U14: =Inputs!$B$3*$D$2^(19-9)*$F$2^9 -> 582.93806 | V14: =Inputs!$B$3*$D$2^(20-9)*$F$2^9 -> 591.20365
L15: =Inputs!$B$3*$D$2^(10-10)*$F$2^10 -> 499.29906 | M15: =Inputs!$B$3*$D$2^(11-10)*$F$2^10 -> 506.37872 | N15: =Inputs!$B$3*$D$2^(12-10)*$F$2^10 -> 513.55876 | O15: =Inputs!$B$3*$D$2^(13-10)*$F$2^10 -> 520.84061 | P15: =Inputs!$B$3*$D$2^(14-10)*$F$2^10 -> 528.22571 | Q15: =Inputs!$B$3*$D$2^(15-10)*$F$2^10 -> 535.71552 | R15: =Inputs!$B$3*$D$2^(16-10)*$F$2^10 -> 543.31153 | S15: =Inputs!$B$3*$D$2^(17-10)*$F$2^10 -> 551.01525 | T15: =Inputs!$B$3*$D$2^(18-10)*$F$2^10 -> 558.82821 | U15: =Inputs!$B$3*$D$2^(19-10)*$F$2^10 -> 566.75194 | V15: =Inputs!$B$3*$D$2^(20-10)*$F$2^10 -> 574.78802
M16: =Inputs!$B$3*$D$2^(11-11)*$F$2^11 -> 492.31838 | N16: =Inputs!$B$3*$D$2^(12-11)*$F$2^11 -> 499.29906 | O16: =Inputs!$B$3*$D$2^(13-11)*$F$2^11 -> 506.37872 | P16: =Inputs!$B$3*$D$2^(14-11)*$F$2^11 -> 513.55876 | Q16: =Inputs!$B$3*$D$2^(15-11)*$F$2^11 -> 520.84061 | R16: =Inputs!$B$3*$D$2^(16-11)*$F$2^11 -> 528.22571 | S16: =Inputs!$B$3*$D$2^(17-11)*$F$2^11 -> 535.71552 | T16: =Inputs!$B$3*$D$2^(18-11)*$F$2^11 -> 543.31153 | U16: =Inputs!$B$3*$D$2^(19-11)*$F$2^11 -> 551.01525 | V16: =Inputs!$B$3*$D$2^(20-11)*$F$2^11 -> 558.82821
N17: =Inputs!$B$3*$D$2^(12-12)*$F$2^12 -> 485.4353 | O17: =Inputs!$B$3*$D$2^(13-12)*$F$2^12 -> 492.31838 | P17: =Inputs!$B$3*$D$2^(14-12)*$F$2^12 -> 499.29906 | Q17: =Inputs!$B$3*$D$2^(15-12)*$F$2^12 -> 506.37872 | R17: =Inputs!$B$3*$D$2^(16-12)*$F$2^12 -> 513.55876 | S17: =Inputs!$B$3*$D$2^(17-12)*$F$2^12 -> 520.84061 | T17: =Inputs!$B$3*$D$2^(18-12)*$F$2^12 -> 528.22571 | U17: =Inputs!$B$3*$D$2^(19-12)*$F$2^12 -> 535.71552 | V17: =Inputs!$B$3*$D$2^(20-12)*$F$2^12 -> 543.31153
O18: =Inputs!$B$3*$D$2^(13-13)*$F$2^13 -> 478.64845 | P18: =Inputs!$B$3*$D$2^(14-13)*$F$2^13 -> 485.4353 | Q18: =Inputs!$B$3*$D$2^(15-13)*$F$2^13 -> 492.31838 | R18: =Inputs!$B$3*$D$2^(16-13)*$F$2^13 -> 499.29906 | S18: =Inputs!$B$3*$D$2^(17-13)*$F$2^13 -> 506.37872 | T18: =Inputs!$B$3*$D$2^(18-13)*$F$2^13 -> 513.55876 | U18: =Inputs!$B$3*$D$2^(19-13)*$F$2^13 -> 520.84061 | V18: =Inputs!$B$3*$D$2^(20-13)*$F$2^13 -> 528.22571
P19: =Inputs!$B$3*$D$2^(14-14)*$F$2^14 -> 471.95649 | Q19: =Inputs!$B$3*$D$2^(15-14)*$F$2^14 -> 478.64845 | R19: =Inputs!$B$3*$D$2^(16-14)*$F$2^14 -> 485.4353 | S19: =Inputs!$B$3*$D$2^(17-14)*$F$2^14 -> 492.31838 | T19: =Inputs!$B$3*$D$2^(18-14)*$F$2^14 -> 499.29906 | U19: =Inputs!$B$3*$D$2^(19-14)*$F$2^14 -> 506.37872 | V19: =Inputs!$B$3*$D$2^(20-14)*$F$2^14 -> 513.55876
Q20: =Inputs!$B$3*$D$2^(15-15)*$F$2^15 -> 465.35809 | R20: =Inputs!$B$3*$D$2^(16-15)*$F$2^15 -> 471.95649 | S20: =Inputs!$B$3*$D$2^(17-15)*$F$2^15 -> 478.64845 | T20: =Inputs!$B$3*$D$2^(18-15)*$F$2^15 -> 485.4353 | U20: =Inputs!$B$3*$D$2^(19-15)*$F$2^15 -> 492.31838 | V20: =Inputs!$B$3*$D$2^(20-15)*$F$2^15 -> 499.29906
R21: =Inputs!$B$3*$D$2^(16-16)*$F$2^16 -> 458.85193 | S21: =Inputs!$B$3*$D$2^(17-16)*$F$2^16 -> 465.35809 | T21: =Inputs!$B$3*$D$2^(18-16)*$F$2^16 -> 471.95649 | U21: =Inputs!$B$3*$D$2^(19-16)*$F$2^16 -> 478.64845 | V21: =Inputs!$B$3*$D$2^(20-16)*$F$2^16 -> 485.4353
S22: =Inputs!$B$3*$D$2^(17-17)*$F$2^17 -> 452.43675 | T22: =Inputs!$B$3*$D$2^(18-17)*$F$2^17 -> 458.85193 | U22: =Inputs!$B$3*$D$2^(19-17)*$F$2^17 -> 465.35809 | V22: =Inputs!$B$3*$D$2^(20-17)*$F$2^17 -> 471.95649
T23: =Inputs!$B$3*$D$2^(18-18)*$F$2^18 -> 446.11125 | U23: =Inputs!$B$3*$D$2^(19-18)*$F$2^18 -> 452.43675 | V23: =Inputs!$B$3*$D$2^(20-18)*$F$2^18 -> 458.85193
U24: =Inputs!$B$3*$D$2^(19-19)*$F$2^19 -> 439.87419 | V24: =Inputs!$B$3*$D$2^(20-19)*$F$2^19 -> 446.11125
V25: =Inputs!$B$3*$D$2^(20-20)*$F$2^20 -> 433.72433
A26: European call value
B27: 0 | C27: 1 | D27: 2 | E27: 3 | F27: 4 | G27: 5 | H27: 6 | I27: 7 | J27: 8 | K27: 9 | L27: 10 | M27: 11 | N27: 12 | O27: 13 | P27: 14 | Q27: 15 | R27: 16 | S27: 17 | T27: 18 | U27: 19 | V27: 20
B28: =$J$2*($H$2*C28+(1-$H$2)*C29) -> 16.437634 | C28: =$J$2*($H$2*D28+(1-$H$2)*D29) -> 20.865868 | D28: =$J$2*($H$2*E28+(1-$H$2)*E29) -> 26.068535 | E28: =$J$2*($H$2*F28+(1-$H$2)*F29) -> 32.043813 | F28: =$J$2*($H$2*G28+(1-$H$2)*G29) -> 38.750184 | G28: =$J$2*($H$2*H28+(1-$H$2)*H29) -> 46.108081 | H28: =$J$2*($H$2*I28+(1-$H$2)*I29) -> 54.009131 | I28: =$J$2*($H$2*J28+(1-$H$2)*J29) -> 62.33237 | ... U28: =$J$2*($H$2*V28+(1-$H$2)*V29) -> 176.28265 | V28: =MAX(V5-Inputs!$B$4,0) -> 186.73102
C29: =$J$2*($H$2*D29+(1-$H$2)*D30) -> 11.836772 | D29: =$J$2*($H$2*E29+(1-$H$2)*E30) -> 15.462118 | E29: =$J$2*($H$2*F29+(1-$H$2)*F30) -> 19.86466 | F29: =$J$2*($H$2*G29+(1-$H$2)*G30) -> 25.083988 | G29: =$J$2*($H$2*H29+(1-$H$2)*H30) -> 31.11822 | H29: =$J$2*($H$2*I29+(1-$H$2)*I30) -> 37.917753 | I29: =$J$2*($H$2*J29+(1-$H$2)*J30) -> 45.387225 | J29: =$J$2*($H$2*K29+(1-$H$2)*K30) -> 53.398 | ... U29: =$J$2*($H$2*V29+(1-$H$2)*V30) -> 155.43092 | V29: =MAX(V6-Inputs!$B$4,0) -> 165.58046
D30: =$J$2*($H$2*E30+(1-$H$2)*E31) -> 8.0682885 | E30: =$J$2*($H$2*F30+(1-$H$2)*F31) -> 10.886966 | F30: =$J$2*($H$2*G30+(1-$H$2)*G31) -> 14.442414 | G30: =$J$2*($H$2*H30+(1-$H$2)*H31) -> 18.817518 | H30: =$J$2*($H$2*I30+(1-$H$2)*I31) -> 24.060179 | I30: =$J$2*($H$2*J30+(1-$H$2)*J31) -> 30.168472 | J30: =$J$2*($H$2*K30+(1-$H$2)*K31) -> 37.081637 | K30: =$J$2*($H$2*L30+(1-$H$2)*L31) -> 44.682463 | ... U30: =$J$2*($H$2*V30+(1-$H$2)*V31) -> 135.15817 | V30: =MAX(V7-Inputs!$B$4,0) -> 145.01717
E31: =$J$2*($H$2*F31+(1-$H$2)*F32) -> 5.1370558 | F31: =$J$2*($H$2*G31+(1-$H$2)*G32) -> 7.1903358 | G31: =$J$2*($H$2*H31+(1-$H$2)*H32) -> 9.8947459 | H31: =$J$2*($H$2*I31+(1-$H$2)*I32) -> 13.369762 | I31: =$J$2*($H$2*J31+(1-$H$2)*J32) -> 17.715312 | J31: =$J$2*($H$2*K31+(1-$H$2)*K32) -> 22.990841 | K31: =$J$2*($H$2*L31+(1-$H$2)*L32) -> 29.194403 | L31: =$J$2*($H$2*M31+(1-$H$2)*M32) -> 36.249062 | ... U31: =$J$2*($H$2*V31+(1-$H$2)*V32) -> 115.44832 | V31: =MAX(V8-Inputs!$B$4,0) -> 125.02486
F32: =$J$2*($H$2*G32+(1-$H$2)*G33) -> 3.000958 | G32: =$J$2*($H$2*H32+(1-$H$2)*H33) -> 4.3773188 | H32: =$J$2*($H$2*I32+(1-$H$2)*I33) -> 6.2809079 | I32: =$J$2*($H$2*J32+(1-$H$2)*J33) -> 8.8517251 | J32: =$J$2*($H$2*K32+(1-$H$2)*K33) -> 12.23204 | K32: =$J$2*($H$2*L32+(1-$H$2)*L33) -> 16.545401 | L32: =$J$2*($H$2*M32+(1-$H$2)*M33) -> 21.868088 | M32: =$J$2*($H$2*N32+(1-$H$2)*N33) -> 28.198189 | ... U32: =$J$2*($H$2*V32+(1-$H$2)*V33) -> 96.285748 | V32: =MAX(V9-Inputs!$B$4,0) -> 105.58766
G33: =$J$2*($H$2*H33+(1-$H$2)*H34) -> 1.5685887 | H33: =$J$2*($H$2*I33+(1-$H$2)*I34) -> 2.3965196 | I33: =$J$2*($H$2*J33+(1-$H$2)*J34) -> 3.6062299 | J33: =$J$2*($H$2*K33+(1-$H$2)*K34) -> 5.3355079 | K33: =$J$2*($H$2*L33+(1-$H$2)*L34) -> 7.7463107 | L33: =$J$2*($H$2*M33+(1-$H$2)*M34) -> 11.011632 | M33: =$J$2*($H$2*N33+(1-$H$2)*N34) -> 15.289398 | N33: =$J$2*($H$2*O33+(1-$H$2)*O34) -> 20.682127 | ... U33: =$J$2*($H$2*V33+(1-$H$2)*V34) -> 77.65525 | V33: =MAX(V10-Inputs!$B$4,0) -> 86.69016
H34: =$J$2*($H$2*I34+(1-$H$2)*I35) -> 0.70670244 | I34: =$J$2*($H$2*J34+(1-$H$2)*J35) -> 1.137313 | J34: =$J$2*($H$2*K34+(1-$H$2)*K35) -> 1.8063986 | K34: =$J$2*($H$2*L34+(1-$H$2)*L35) -> 2.8266899 | L34: =$J$2*($H$2*M34+(1-$H$2)*M35) -> 4.3488125 | M34: =$J$2*($H$2*N34+(1-$H$2)*N35) -> 6.5616702 | N34: =$J$2*($H$2*O34+(1-$H$2)*O35) -> 9.6811631 | O34: =$J$2*($H$2*P34+(1-$H$2)*P35) -> 13.918697 | ... U34: =$J$2*($H$2*V34+(1-$H$2)*V35) -> 59.542054 | V34: =MAX(V11-Inputs!$B$4,0) -> 68.317379
I35: =$J$2*($H$2*J35+(1-$H$2)*J36) -> 0.25830971 | J35: =$J$2*($H$2*K35+(1-$H$2)*K36) -> 0.44064117 | K35: =$J$2*($H$2*L35+(1-$H$2)*L36) -> 0.74412151 | L35: =$J$2*($H$2*M35+(1-$H$2)*M36) -> 1.2420778 | M35: =$J$2*($H$2*N35+(1-$H$2)*N36) -> 2.0453749 | N35: =$J$2*($H$2*O35+(1-$H$2)*O36) -> 3.3149671 | O35: =$J$2*($H$2*P35+(1-$H$2)*P36) -> 5.2716828 | P35: =$J$2*($H$2*Q35+(1-$H$2)*Q36) -> 8.1937756 | ... U35: =$J$2*($H$2*V35+(1-$H$2)*V36) -> 41.931797 | V35: =MAX(V12-Inputs!$B$4,0) -> 50.454743
J36: =$J$2*($H$2*K36+(1-$H$2)*K37) -> 0.068403141 | K36: =$J$2*($H$2*L36+(1-$H$2)*L37) -> 0.12456446 | L36: =$J$2*($H$2*M36+(1-$H$2)*M37) -> 0.22552037 | M36: =$J$2*($H$2*N36+(1-$H$2)*N37) -> 0.40552323 | N36: =$J$2*($H$2*O36+(1-$H$2)*O37) -> 0.72331201 | O36: =$J$2*($H$2*P36+(1-$H$2)*P37) -> 1.2775642 | P36: =$J$2*($H$2*Q36+(1-$H$2)*Q37) -> 2.229453 | Q36: =$J$2*($H$2*R36+(1-$H$2)*R37) -> 3.8317155 | ... U36: =$J$2*($H$2*V36+(1-$H$2)*V37) -> 24.810515 | V36: =MAX(V13-Inputs!$B$4,0) -> 33.08809
K37: =$J$2*($H$2*L37+(1-$H$2)*L38) -> 0.0098960992 | L37: =$J$2*($H$2*M37+(1-$H$2)*M38) -> 0.019393642 | M37: =$J$2*($H$2*N37+(1-$H$2)*N38) -> 0.038006224 | N37: =$J$2*($H$2*O37+(1-$H$2)*O38) -> 0.074481782 | O37: =$J$2*($H$2*P37+(1-$H$2)*P38) -> 0.14596388 | P37: =$J$2*($H$2*Q37+(1-$H$2)*Q38) -> 0.2860492 | Q37: =$J$2*($H$2*R37+(1-$H$2)*R38) -> 0.56057804 | R37: =$J$2*($H$2*S37+(1-$H$2)*S38) -> 1.0985793 | ... U37: =$J$2*($H$2*V37+(1-$H$2)*V38) -> 8.268323 | V37: =MAX(V14-Inputs!$B$4,0) -> 16.203647
L38: =$J$2*($H$2*M38+(1-$H$2)*M39) -> 0 | M38: =$J$2*($H$2*N38+(1-$H$2)*N39) -> 0 | N38: =$J$2*($H$2*O38+(1-$H$2)*O39) -> 0 | O38: =$J$2*($H$2*P38+(1-$H$2)*P39) -> 0 | P38: =$J$2*($H$2*Q38+(1-$H$2)*Q39) -> 0 | Q38: =$J$2*($H$2*R38+(1-$H$2)*R39) -> 0 | R38: =$J$2*($H$2*S38+(1-$H$2)*S39) -> 0 | S38: =$J$2*($H$2*T38+(1-$H$2)*T39) -> 0 | ... U38: =$J$2*($H$2*V38+(1-$H$2)*V39) -> 0 | V38: =MAX(V15-Inputs!$B$4,0) -> 0
M39: =$J$2*($H$2*N39+(1-$H$2)*N40) -> 0 | N39: =$J$2*($H$2*O39+(1-$H$2)*O40) -> 0 | O39: =$J$2*($H$2*P39+(1-$H$2)*P40) -> 0 | P39: =$J$2*($H$2*Q39+(1-$H$2)*Q40) -> 0 | Q39: =$J$2*($H$2*R39+(1-$H$2)*R40) -> 0 | R39: =$J$2*($H$2*S39+(1-$H$2)*S40) -> 0 | S39: =$J$2*($H$2*T39+(1-$H$2)*T40) -> 0 | T39: =$J$2*($H$2*U39+(1-$H$2)*U40) -> 0 | U39: =$J$2*($H$2*V39+(1-$H$2)*V40) -> 0 | V39: =MAX(V16-Inputs!$B$4,0) -> 0
N40: =$J$2*($H$2*O40+(1-$H$2)*O41) -> 0 | O40: =$J$2*($H$2*P40+(1-$H$2)*P41) -> 0 | P40: =$J$2*($H$2*Q40+(1-$H$2)*Q41) -> 0 | Q40: =$J$2*($H$2*R40+(1-$H$2)*R41) -> 0 | R40: =$J$2*($H$2*S40+(1-$H$2)*S41) -> 0 | S40: =$J$2*($H$2*T40+(1-$H$2)*T41) -> 0 | T40: =$J$2*($H$2*U40+(1-$H$2)*U41) -> 0 | U40: =$J$2*($H$2*V40+(1-$H$2)*V41) -> 0 | V40: =MAX(V17-Inputs!$B$4,0) -> 0
...

Sheet MC_Shocks
A1: Standard-normal draws, seed 42. Rows 251-500 are the antithetic mirror of rows 1-250.
A2: 0.49671415 | B2: -0.1382643 | C2: 0.64768854 | D2: 1.5230299 | E2: -0.23415337 | F2: -0.23413696 | G2: 1.5792128 | H2: 0.76743473 | I2: -0.46947439 | J2: 0.54256004 | K2: -0.46341769 | L2: -0.46572975 | M2: 0.24196227 | N2: -1.9132802 | O2: -1.7249178 | P2: -0.56228753 | Q2: -1.0128311 | R2: 0.31424733 | S2: -0.90802408 | T2: -1.4123037 | U2: 1.4656488 | V2: -0.2257763 | W2: 0.067528205 | X2: -1.4247482 | Y2: -0.54438272 | Z2: 0.11092259 | AA2: -1.1509936 | AB2: 0.37569802 | AC2: -0.60063869 | AD2: -0.29169375 | AE2: -0.60170661 | AF2: 1.8522782 | AG2: -0.013497225 | AH2: -1.0577109 | AI2: 0.82254491 | AJ2: -1.2208436 | AK2: 0.2088636 | AL2: -1.9596701 | AM2: -1.328186 | AN2: 0.19686124 | AO2: 0.73846658 | AP2: 0.17136828 | AQ2: -0.11564828 | AR2: -0.3011037 | AS2: -1.478522 | AT2: -0.71984421 | AU2: -0.46063877 | AV2: 1.0571222 | AW2: 0.34361829 | AX2: -1.7630402 | AY2: 0.32408397 | AZ2: -0.38508228 | BA2: -0.676922 | BB2: 0.61167629 | BC2: 1.0309995 | BD2: 0.93128012 | BE2: -0.83921752 | BF2: -0.30921238 | BG2: 0.33126343 | BH2: 0.97554513 | BI2: -0.47917424 | BJ2: -0.18565898 | BK2: -1.106335
A3: -1.1962066 | B3: 0.81252582 | C3: 1.35624 | D3: -0.072010122 | E3: 1.0035329 | F3: 0.36163603 | G3: -0.64511975 | H3: 0.36139561 | I3: 1.5380366 | J3: -0.035826039 | K3: 1.5646437 | L3: -2.6197451 | M3: 0.8219025 | N3: 0.087047068 | O3: -0.29900735 | P3: 0.091760777 | Q3: -1.9875689 | R3: -0.21967189 | S3: 0.35711257 | T3: 1.477894 | U3: -0.51827022 | V3: -0.8084936 | W3: -0.50175704 | X3: 0.91540212 | Y3: 0.32875111 | Z3: -0.5297602 | AA3: 0.51326743 | AB3: 0.097077549 | AC3: 0.96864499 | AD3: -0.70205309 | AE3: -0.32766215 | AF3: -0.39210815 | AG3: -1.4635149 | AH3: 0.29612028 | AI3: 0.26105527 | AJ3: 0.0051134566 | AK3: -0.23458713 | AL3: -1.4153707 | AM3: -0.42064532 | AN3: -0.34271452 | AO3: -0.80227727 | AP3: -0.16128571 | AQ3: 0.40405086 | AR3: 1.8861859 | AS3: 0.17457781 | AT3: 0.25755039 | AU3: -0.074445916 | AV3: -1.9187712 | AW3: -0.026513875 | AX3: 0.06023021 | AY3: 2.4632421 | AZ3: -0.19236096 | BA3: 0.30154734 | BB3: -0.03471177 | BC3: -1.168678 | BD3: 1.1428228 | BE3: 0.75193303 | BF3: 0.79103195 | BG3: -0.90938745 | BH3: 1.4027943 | BI3: -1.4018511 | BJ3: 0.58685709 | BK3: 2.1904556
A4: -0.99053633 | B4: -0.56629773 | C4: 0.099651365 | D4: -0.50347565 | E4: -1.5506634 | F4: 0.068562975 | G4: -1.0623037 | H4: 0.47359243 | I4: -0.91942423 | J4: 1.5499344 | K4: -0.78325329 | L4: -0.32206152 | M4: 0.81351722 | N4: -1.2308643 | O4: 0.22745993 | P4: 1.3071428 | Q4: -1.6074832 | R4: 0.18463386 | S4: 0.25988279 | T4: 0.78182287 | U4: -1.2369507 | V4: -1.3204566 | W4: 0.52194157 | X4: 0.29698467 | Y4: 0.25049285 | Z4: 0.34644821 | AA4: -0.68002472 | AB4: 0.2322537 | AC4: 0.29307247 | AD4: -0.71435142 | AE4: 1.8657745 | AF4: 0.47383292 | AG4: -1.1913035 | AH4: 0.65655361 | AI4: -0.97468167 | AJ4: 0.7870846 | AK4: 1.1585956 | AL4: -0.82068232 | AM4: 0.96337613 | AN4: 0.41278093 | AO4: 0.82206016 | AP4: 1.896793 | AQ4: -0.24538812 | AR4: -0.75373616 | AS4: -0.88951443 | AT4: -0.81581028 | AU4: -0.077101709 | AV4: 0.34115197 | AW4: 0.2766908 | AX4: 0.82718325 | AY4: 0.013001892 | AZ4: 1.4535341 | BA4: -0.26465683 | BB4: 2.7201692 | BC4: 0.62566735 | BD4: -0.85715756 | BE4: -1.0708925 | BF4: 0.48247242 | BG4: -0.22346279 | BH4: 0.71400049 | BI4: 0.47323762 | BJ4: -0.072828913 | BK4: -0.84679372
A5: -1.5148472 | B5: -0.44651495 | C5: 0.85639879 | D5: 0.21409374 | E5: -1.2457388 | F5: 0.17318093 | G5: 0.38531738 | H5: -0.88385744 | I5: 0.15372511 | J5: 0.058208718 | K5: -1.1429703 | L5: 0.35778736 | M5: 0.56078453 | N5: 1.0830512 | O5: 1.0538021 | P5: -1.3776694 | Q5: -0.93782504 | R5: 0.51503527 | S5: 0.51378595 | T5: 0.51504769 | U5: 3.8527315 | V5: 0.57089051 | W5: 1.1355656 | X5: 0.95400176 | Y5: 0.65139125 | Z5: -0.31526924 | AA5: 0.75896922 | AB5: -0.77282521 | AC5: -0.23681861 | AD5: -0.48536355 | AE5: 0.081874139 | AF5: 2.3146586 | AG5: -1.8672652 | AH5: 0.68626019 | AI5: -1.6127159 | AJ5: -0.47193187 | AK5: 1.0889506 | AL5: 0.064280019 | AM5: -1.0777448 | AN5: -0.71530371 | AO5: 0.67959775 | AP5: -0.73036663 | AQ5: 0.21645859 | AR5: 0.04557184 | AS5: -0.65160035 | AT5: 2.1439441 | AU5: 0.63391902 | AV5: -2.0251426 | AW5: 0.18645431 | AX5: -0.66178646 | AY5: 0.85243333 | AZ5: -0.79252074 | BA5: -0.11473644 | BB5: 0.50498728 | BC5: 0.86575519 | BD5: -1.2002964 | BE5: -0.33450124 | BF5: -0.47494531 | BG5: -0.65332923 | BH5: 1.7654542 | BI5: 0.40498171 | BJ5: -1.260884 | BK5: 0.91786195
A6: 2.1221562 | B6: 1.0324653 | C6: -1.51937 | D6: -0.48423407 | E6: 1.2669111 | F6: -0.70766947 | G6: 0.44381943 | H6: 0.77463405 | I6: -0.92693047 | J6: -0.059525356 | K6: -3.2412673 | L6: -1.0243876 | M6: -0.25256815 | N6: -1.2477832 | O6: 1.6324113 | P6: -1.4301414 | Q6: -0.44004449 | R6: 0.13074058 | S6: 1.4412733 | T6: -1.4358622 | U6: 1.1631638 | V6: 0.010233061 | W6: -0.98150865 | X6: 0.46210347 | Y6: 0.1990597 | Z6: -0.60021688 | AA6: 0.069802085 | AB6: -0.3853136 | AC6: 0.11351735 | AD6: 0.66213067 | AE6: 1.5860168 | AF6: -1.2378155 | AG6: 2.1330334 | AH6: -1.9520878 | AI6: -0.1517851 | AJ6: 0.58831721 | AK6: 0.28099187 | AL6: -0.62269952 | AM6: -0.20812225 | AN6: -0.49300093 | AO6: -0.58936476 | AP6: 0.8496021 | AQ6: 0.35701549 | AR6: -0.6929096 | AS6: 0.89959988 | AT6: 0.30729952 | AU6: 0.81286212 | AV6: 0.62962884 | AW6: -0.82899501 | AX6: -0.56018104 | AY6: 0.74729361 | AZ6: 0.61037027 | BA6: -0.020901594 | BB6: 0.11732738 | BC6: 1.2776649 | BD6: -0.59157139 | BE6: 0.54709738 | BF6: -0.20219265 | BG6: -0.2176812 | BH6: 1.0987769 | BI6: 0.82541635 | BJ6: 0.81350964 | BK6: 1.3054788
A7: 0.021003842 | B7: 0.68195297 | C7: -0.31026676 | D7: 0.32416635 | E7: -0.13014305 | F7: 0.096995965 | G7: 0.59515703 | H7: -0.81822068 | I7: 2.0923873 | J7: -1.0060174 | K7: -1.2141886 | L7: 1.1581109 | M7: 0.79166269 | N7: 0.62411982 | O7: 0.62834551 | P7: -0.012246773 | Q7: -0.89725437 | R7: 0.075804558 | S7: -0.67716171 | T7: 0.97511973 | U7: -0.14705738 | V7: -0.8254972 | W7: -0.32138584 | X7: 0.41293145 | Y7: -0.56372455 | Z7: -0.8222204 | AA7: 0.24368721 | AB7: 0.24496657 | AC7: -0.50694318 | AD7: -0.47103831 | AE7: 0.23204994 | AF7: -1.4480843 | AG7: -1.4074638 | AH7: -0.71844422 | AI7: -0.21344715 | AJ7: 0.31090757 | AK7: 1.4753562 | AL7: 0.85765962 | AM7: -0.15993853 | AN7: -0.019016208 | AO7: -1.0025294 | AP7: -0.018513136 | AQ7: -0.28865864 | AR7: 0.32271856 | AS7: -0.82723094 | AT7: 0.51934651 | AU7: 1.5327389 | AV7: -0.10876015 | AW7: 0.40171172 | AX7: 0.69014399 | AY7: -0.40122047 | AZ7: 0.22409248 | BA7: 0.012592401 | BB7: 0.097676099 | BC7: -0.77300978 | BD7: 0.024510174 | BE7: 0.49799829 | BF7: 1.4511436 | BG7: 0.95927083 | BH7: 2.1531825 | BI7: -0.76734756 | BJ7: 0.87232064 | BK7: 0.18334201
A8: 2.1898029 | B8: -0.80829829 | C8: -0.83972184 | D8: -0.59939265 | E8: -2.1238957 | F8: -0.52575502 | G8: -0.75913266 | H8: 0.15039379 | I8: 0.34175598 | J8: 1.8761708 | K8: 0.95042384 | L8: -0.57690366 | M8: -0.89841467 | N8: 0.49191917 | O8: -1.3202332 | P8: 1.8314588 | Q8: 1.1794401 | R8: -0.46917565 | S8: -1.7131345 | T8: 1.3538724 | U8: -0.11453985 | V8: 1.2378163 | W8: -1.5944277 | X8: -0.59937502 | Y8: 0.0052436997 | Z8: 0.046980594 | AA8: -0.45006547 | AB8: 0.62284993 | AC8: -1.0676204 | AD8: -0.14237949 | AE8: 0.12029563 | AF8: 0.51443883 | AG8: 0.71161488 | AH8: -1.1246421 | AI8: -1.5341142 | AJ8: 1.2776768 | AK8: 0.33231401 | AL8: -0.74848654 | AM8: 1.551152 | AN8: 0.11567463 | AO8: 1.1792972 | AP8: 0.067518481 | AQ8: 2.0607479 | AR8: 1.7553408 | AS8: -0.24896415 | AT8: 0.97157095 | AU8: 0.64537595 | AV8: 1.3686316 | AW8: -0.96492346 | AX8: 0.68605146 | AY8: 1.0584245 | AZ8: -1.7587395 | BA8: -1.1832585 | BB8: -2.0392322 | BC8: -0.26940683 | BD8: 0.71754226 | BE8: 1.5023571 | BF8: 0.07409478 | BG8: 1.6286155 | BH8: -1.3801015 | BI8: -1.7033824 | BJ8: -0.055547699 | BK8: 0.38406545
A9: -0.032694748 | B9: -2.0674421 | C9: -0.08912004 | D9: -1.3044695 | E9: 0.66967255 | F9: 0.36659825 | G9: -0.93987979 | H9: -0.51386692 | I9: -1.0592135 | J9: -0.062679097 | K9: 0.95514232 | L9: -0.98572605 | M9: 0.50404652 | N9: -0.53025762 | O9: -0.79287283 | P9: -0.10703036 | Q9: -1.0352423 | R9: -0.55364931 | S9: -1.1978779 | T9: 1.9647251 | U9: 0.035263552 | V9: -0.69972551 | W9: 0.21397991 | X9: -0.11232805 | Y9: -0.2209696 | Z9: 0.6141667 | AA9: 0.75750771 | AB9: -0.53050115 | AC9: -0.57581824 | AD9: -0.2750517 | AE9: -2.3019212 | AF9: -1.5151911 | AG9: 1.3668743 | AH9: 1.6449677 | AI9: -0.24903604 | AJ9: 0.57655696 | AK9: 0.31125015 | AL9: 3.0788808 | AM9: 1.1195749 | AN9: -0.12791759 | AO9: -0.95554044 | AP9: -1.6064463 | AQ9: 0.20346364 | AR9: -0.75635075 | AS9: -1.4222537 | AT9: -0.64657288 | AU9: -1.081548 | AV9: 1.6871416 | AW9: 0.88163976 | AX9: -0.0079726413 | AY9: 1.4799441 | AZ9: 0.077368308 | BA9: -0.8612842 | BB9: 1.5231241 | BC9: 0.53891004 | BD9: -1.0372462 | BE9: -0.19033868 | BF9: -0.87561825 | BG9: -1.3827997 | BH9: 0.92617755 | BI9: 1.9094166 | BJ9: -1.3985676 | BK9: 0.56296924
A10: -0.65064257 | B10: -0.48712538 | C10: -0.59239392 | D10: -0.86399077 | E10: 0.048521628 | F10: -0.83095012 | G10: 0.27045683 | H10: -0.050238109 | I10: -0.23894805 | J10: -0.90756366 | K10: -0.57677133 | L10: 0.75539123 | M10: 0.50091719 | N10: -0.97755524 | O10: 0.099332305 | P10: 0.75138712 | Q10: -1.6694053 | R10: 0.54336019 | S10: -0.66262376 | T10: 0.57059867 | U10: -0.76325916 | V10: -1.8048821 | W10: -1.6275424 | X10: 0.048084947 | Y10: 0.2597225 | Z10: -0.90431663 | AA10: 0.63859246 | AB10: -1.6615201 | AC10: -0.066079799 | AD10: -1.2110162 | AE10: -0.65183611 | AF10: 0.047398671 | AG10: -0.86041337 | AH10: -0.38455554 | AI10: 1.0062928 | AJ10: -0.57689187 | AK10: 0.83569211 | AL10: -1.1297069 | AM10: 0.52980418 | AN10: 1.4415686 | AO10: -2.4716445 | AP10: -0.79689526 | AQ10: 0.57707213 | AR10: -0.20304539 | AS10: 0.37114587 | AT10: -0.60398519 | AU10: 0.086589787 | AV10: -0.15567724 | AW10: 1.1677821 | AX10: 0.25442084 | AY10: 0.33760266 | AZ10: -0.41187697 | BA10: -0.48760622 | BB10: -0.43255819 | BC10: 0.39445214 | BD10: -0.42098448 | BE10: 0.28977486 | BF10: 2.0754008 | BG10: 0.8711247 | BH10: -0.32602353 | BI10: 1.2012139 | BJ10: -0.40807537 | BK10: -2.0381245
A11: -1.0080863 | B11: -1.8707919 | C11: -0.35151348 | D11: 0.018418379 | E11: 1.6764373 | F11: 0.32692737 | G11: -0.21910053 | H11: 0.82940558 | I11: -2.2111353 | J11: 0.23561456 | K11: 0.77086519 | L11: -1.4785862 | M11: 1.143754 | N11: 0.33849641 | O11: -0.41528791 | P11: 0.63278187 | Q11: 2.2706929 | R11: 0.18186626 | S11: 0.24822059 | T11: -0.4593609 | U11: -0.84984437 | V11: 0.83033582 | W11: -0.85608383 | X11: 0.071566237 | Y11: -0.47765745 | Z11: 0.47897983 | AA11: 0.33366211 | AB11: 1.0375399 | AC11: -0.5100164 | AD11: -0.26987494 | AE11: -0.97876372 | AF11: -0.44429326 | AG11: 0.37730049 | AH11: 0.75698862 | AI11: -0.92216532 | AJ11: 0.86960592 | AK11: 1.3556379 | AL11: 0.4134349 | AM11: 1.8767958 | AN11: -0.7737892 | AO11: -1.2446547 | AP11: -1.7787202 | AQ11: 1.4960443 | AR11: 0.65436566 | AS11: -0.055584671 | AT11: 0.27996863 | AU11: -1.125489 | AV11: 2.445752 | AW11: 0.12922118 | AX11: 0.10939479 | AY11: 0.72576662 | AZ11: 0.48100923 | BA11: 0.22388402 | BB11: -0.79047446 | BC11: 0.47146836 | BD11: 1.8820245 | BE11: 1.34542 | BF11: 1.5931866 | BG11: -0.51121568 | BH11: -0.98960482 | BI11: -0.12578692 | BJ11: 0.055724912 | BK11: 1.0941915
A12: -1.6924646 | B12: 1.5295503 | C12: -0.1580079 | D12: -0.42688107 | E12: -1.0121044 | F12: -1.6548567 | G12: 0.82317058 | H12: 0.073317967 | I12: -1.2899609 | J12: -1.2950788 | K12: -0.3357847 | L12: 1.6690215 | M12: -0.25959135 | N12: -1.503143 | O12: -0.24574306 | P12: -0.27272357 | Q12: -2.6968866 | R12: -0.054294867 | S12: -0.23093453 | T12: 0.69620636 | U12: 1.8489561 | V12: 1.126565 | W12: -0.26888869 | X12: -1.1065259 | Y12: 2.5733598 | Z12: 0.059218434 | AA12: 0.013929292 | AB12: -0.024125087 | AC12: 0.19808476 | AD12: -0.14436041 | AE12: -0.57366201 | AF12: -0.54685894 | AG12: -0.03275327 | AH12: -0.54342477 | AI12: -0.71284578 | AJ12: 0.10643023 | AK12: -0.25497722 | AL12: 1.503993 | AM12: -2.6509698 | AN12: 1.0915069 | AO12: 1.2460852 | AP12: -2.0733902 | AQ12: -0.34268759 | AR12: -0.37144087 | AS12: -1.4075117 | AT12: -0.77781669 | AU12: -1.1105758 | AV12: 1.7522704 | AW12: 0.93567839 | AX12: 1.2715551 | AY12: 0.72167206 | AZ12: -1.1290518 | BA12: -0.52452027 | BB12: 0.48937456 | BC12: -1.2221278 | BD12: 0.71299843 | BE12: -0.2403254 | BF12: -0.37482081 | BG12: 0.71095997 | BH12: 0.44426331 | BI12: -0.36096617 | BJ12: 1.1593298 | BK12: -1.0810633
A13: 0.61593561 | B13: 0.59310126 | C13: -0.30954644 | D13: 0.32613302 | E13: -1.2511136 | F13: 0.92402702 | G13: -0.18490214 | H13: -0.52272302 | I13: 1.0490092 | J13: -0.70434369 | K13: -1.4084613 | L13: -1.5566292 | M13: 0.60600995 | N13: -1.2804294 | O13: 1.7547942 | P13: -2.0819294 | Q13: 1.6964564 | R13: 0.21101747 | S13: -0.096713112 | T13: -0.54491909 | U13: 0.39913611 | V13: -0.037634702 | W13: 1.1033019 | X13: 0.11422765 | Y13: 0.15030176 | Z13: -0.36361221 | AA13: -0.056945624 | AB13: 0.30780177 | AC13: -1.7101684 | AD13: -1.3481854 | AE13: 0.74326409 | AF13: 0.17086544 | AG13: -0.18398334 | AH13: 0.018433933 | AI13: 0.34758171 | AJ13: -0.53975968 | AK13: -0.77830473 | AL13: 0.19584526 | AM13: -0.97837278 | AN13: 0.40825276 | AO13: -1.7025836 | AP13: 1.0291556 | AQ13: 0.47259748 | AR13: 0.25602973 | AS13: 0.98269098 | AT13: 1.6654744 | AU13: 1.0143701 | AV13: -1.8408742 | AW13: -1.279577 | AX13: -0.62481858 | AY13: 0.02609105 | AZ13: 0.51765902 | BA13: -0.72574381 | BB13: 0.18676676 | BC13: -0.75538293 | BD13: -0.6115178 | BE13: -1.4066611 | BF13: -0.92323325 | BG13: -1.3516846 | BH13: -0.97587325 | BI13: 1.0536418 | BJ13: -0.94939889 | BK13: 2.6323821
... A501: -0.29374735 | B501: -0.32659596 | C501: 0.51331309 | D501: -0.7837314 | E501: 1.398098 | F501: 0.24439984 | G501: -0.55585846 | H501: 0.28758415 | I501: 0.2067544 | J501: 0.13778586 | K501: 0.83560124 | L501: -1.1739009 | M501: 1.0180377 | N501: -0.31815933 | O501: -0.4136479 | P501: 0.9486219 | Q501: -0.073104254 | R501: 0.90963217 | S501: -1.3910425 | T501: 1.1387829 | U501: 0.65389709 | V501: 1.224225 | W501: 1.3576987 | X501: -1.5912153 | Y501: -0.54277467 | Z501: -0.14029343 | AA501: 0.65657696 | AB501: -0.90761181 | AC501: 0.82422244 | AD501: -0.79363929 | AE501: 0.87251128 | AF501: 0.6445077 | AG501: -0.75828239 | AH501: -0.86382734 | AI501: -0.59747293 | AJ501: 1.0496741 | AK501: 0.44672687 | AL501: -0.15689874 | AM501: 0.84928096 | AN501: -1.3709628 | AO501: 2.4019469 | AP501: 0.77873952 | AQ501: 0.5095665 | AR501: 2.8439437 | AS501: 1.3962291 | AT501: -0.62528951 | AU501: -0.030283637 | AV501: -1.573136 | AW501: -1.5452264 | AX501: -0.43304638 | AY501: -0.31323825 | AZ501: -0.065931109 | BA501: 2.655082 | BB501: 1.3945595 | BC501: -0.1006755 | BD501: -0.61602571 | BE501: -0.28966981 | BF501: 0.89246497 | BG501: -0.93740628 | BH501: -1.482444 | BI501: -0.9379896 | BJ501: -0.98959933 | BK501: 0.5592258

Sheet MC_Paths
A1: Risk-neutral GBM paths: S(t+dt) = S(t) exp((r-q-0.5 sigma^2) dt + sigma sqrt(dt) Z)
A2: dt | B2: =Inputs!B5/Inputs!B11 -> 0.003968254
A4: path | B4: t0 | C4: t1 | D4: t2 | E4: t3 | F4: t4 | G4: t5 | H4: t6 | I4: t7 | J4: t8 | K4: t9 | L4: t10 | M4: t11 | N4: t12 | O4: t13 | P4: t14 | Q4: t15 | R4: t16 | S4: t17 | T4: t18 | U4: t19 | V4: t20 | W4: t21 | X4: t22 | Y4: t23 | Z4: t24 | AA4: t25 | AB4: t26 | AC4: t27 | AD4: t28 | AE4: t29 | AF4: t30 | AG4: t31 | AH4: t32 | AI4: t33 | AJ4: t34 | AK4: t35 | AL4: t36 | AM4: t37 | AN4: t38 | AO4: t39 | AP4: t40 | AQ4: t41 | AR4: t42 | AS4: t43 | AT4: t44 | AU4: t45 | AV4: t46 | AW4: t47 | AX4: t48 | AY4: t49 | AZ4: t50 | BA4: t51 | BB4: t52 | BC4: t53 | BD4: t54 | BE4: t55 | BF4: t56 | BG4: t57 | BH4: t58 | BI4: t59 | BJ4: t60 | BK4: t61 | BL4: t62 | BM4: t63 | BN4: Average | BO4: Max | BP4: European call | BQ4: European put | BR4: Asian call | BS4: Up-and-out call
A5: 1 | B5: =Inputs!$B$3 -> 574.78802 | C5: =B5*EXP((Inputs!$B$6-Inputs!$B$7-0.5*Inputs!$B$8^2)*$B$2+Inputs!$B$8*SQRT($B$2)*MC_Shocks!A2) -> 577.11183 | D5: =C5*EXP((Inputs!$B$6-Inputs!$B$7-0.5*Inputs!$B$8^2)*$B$2+Inputs!$B$8*SQRT($B$2)*MC_Shocks!B2) -> 576.53356 | E5: =D5*EXP((Inputs!$B$6-Inputs!$B$7-0.5*Inputs!$B$8^2)*$B$2+Inputs!$B$8*SQRT($B$2)*MC_Shocks!C2) -> 579.55813 | F5: =E5*EXP((Inputs!$B$6-Inputs!$B$7-0.5*Inputs!$B$8^2)*$B$2+Inputs!$B$8*SQRT($B$2)*MC_Shocks!D2) -> 586.65823 | G5: =F5*EXP((Inputs!$B$6-Inputs!$B$7-0.5*Inputs!$B$8^2)*$B$2+Inputs!$B$8*SQRT($B$2)*MC_Shocks!E2) -> 585.62475 | H5: =G5*EXP((Inputs!$B$6-Inputs!$B$7-0.5*Inputs!$B$8^2)*$B$2+Inputs!$B$8*SQRT($B$2)*MC_Shocks!F2) -> 584.59316 | I5: =H5*EXP((Inputs!$B$6-Inputs!$B$7-0.5*Inputs!$B$8^2)*$B$2+Inputs!$B$8*SQRT($B$2)*MC_Shocks!G2) -> 592.01875 | J5: =I5*EXP((Inputs!$B$6-Inputs!$B$7-0.5*Inputs!$B$8^2)*$B$2+Inputs!$B$8*SQRT($B$2)*MC_Shocks!H2) -> 595.69016 | ... BM5: =BL5*EXP((Inputs!$B$6-Inputs!$B$7-0.5*Inputs!$B$8^2)*$B$2+Inputs!$B$8*SQRT($B$2)*MC_Shocks!BK2) -> 529.68431 | BN5: =AVERAGE(C5:BM5) -> 555.50757 | BO5: =MAX(B5:BM5) -> 596.14809 | BP5: =MAX(BM5-Inputs!$B$4,0) -> 0 | BQ5: =MAX(Inputs!$B$4-BM5,0) -> 45.315692 | BR5: =MAX(BN5-Inputs!$B$4,0) -> 0 | BS5: =IF(BO5>=Inputs!$B$9,0,MAX(BM5-Inputs!$B$4,0)) -> 0
A6: 2 | B6: =Inputs!$B$3 -> 574.78802 | C6: =B6*EXP((Inputs!$B$6-Inputs!$B$7-0.5*Inputs!$B$8^2)*$B$2+Inputs!$B$8*SQRT($B$2)*MC_Shocks!A3) -> 569.4131 | D6: =C6*EXP((Inputs!$B$6-Inputs!$B$7-0.5*Inputs!$B$8^2)*$B$2+Inputs!$B$8*SQRT($B$2)*MC_Shocks!B3) -> 573.14931 | E6: =D6*EXP((Inputs!$B$6-Inputs!$B$7-0.5*Inputs!$B$8^2)*$B$2+Inputs!$B$8*SQRT($B$2)*MC_Shocks!C3) -> 579.40376 | F6: =E6*EXP((Inputs!$B$6-Inputs!$B$7-0.5*Inputs!$B$8^2)*$B$2+Inputs!$B$8*SQRT($B$2)*MC_Shocks!D3) -> 579.1275 | G6: =F6*EXP((Inputs!$B$6-Inputs!$B$7-0.5*Inputs!$B$8^2)*$B$2+Inputs!$B$8*SQRT($B$2)*MC_Shocks!E3) -> 583.81139 | H6: =G6*EXP((Inputs!$B$6-Inputs!$B$7-0.5*Inputs!$B$8^2)*$B$2+Inputs!$B$8*SQRT($B$2)*MC_Shocks!F3) -> 585.54389 | I6: =H6*EXP((Inputs!$B$6-Inputs!$B$7-0.5*Inputs!$B$8^2)*$B$2+Inputs!$B$8*SQRT($B$2)*MC_Shocks!G3) -> 582.60985 | J6: =I6*EXP((Inputs!$B$6-Inputs!$B$7-0.5*Inputs!$B$8^2)*$B$2+Inputs!$B$8*SQRT($B$2)*MC_Shocks!H3) -> 584.33767 | ... BM6: =BL6*EXP((Inputs!$B$6-Inputs!$B$7-0.5*Inputs!$B$8^2)*$B$2+Inputs!$B$8*SQRT($B$2)*MC_Shocks!BK3) -> 597.8514 | BN6: =AVERAGE(C6:BM6) -> 581.91209 | BO6: =MAX(B6:BM6) -> 598.89796 | BP6: =MAX(BM6-Inputs!$B$4,0) -> 22.851403 | BQ6: =MAX(Inputs!$B$4-BM6,0) -> 0 | BR6: =MAX(BN6-Inputs!$B$4,0) -> 6.912089 | BS6: =IF(BO6>=Inputs!$B$9,0,MAX(BM6-Inputs!$B$4,0)) -> 22.851403
A7: 3 | B7: =Inputs!$B$3 -> 574.78802 | C7: =B7*EXP((Inputs!$B$6-Inputs!$B$7-0.5*Inputs!$B$8^2)*$B$2+Inputs!$B$8*SQRT($B$2)*MC_Shocks!A4) -> 570.3429 | D7: =C7*EXP((Inputs!$B$6-Inputs!$B$7-0.5*Inputs!$B$8^2)*$B$2+Inputs!$B$8*SQRT($B$2)*MC_Shocks!B4) -> 567.83999 | E7: =D7*EXP((Inputs!$B$6-Inputs!$B$7-0.5*Inputs!$B$8^2)*$B$2+Inputs!$B$8*SQRT($B$2)*MC_Shocks!C4) -> 568.34267 | F7: =E7*EXP((Inputs!$B$6-Inputs!$B$7-0.5*Inputs!$B$8^2)*$B$2+Inputs!$B$8*SQRT($B$2)*MC_Shocks!D4) -> 566.13061 | G7: =F7*EXP((Inputs!$B$6-Inputs!$B$7-0.5*Inputs!$B$8^2)*$B$2+Inputs!$B$8*SQRT($B$2)*MC_Shocks!E4) -> 559.26185 | H7: =G7*EXP((Inputs!$B$6-Inputs!$B$7-0.5*Inputs!$B$8^2)*$B$2+Inputs!$B$8*SQRT($B$2)*MC_Shocks!F4) -> 559.6189 | I7: =H7*EXP((Inputs!$B$6-Inputs!$B$7-0.5*Inputs!$B$8^2)*$B$2+Inputs!$B$8*SQRT($B$2)*MC_Shocks!G4) -> 554.97503 | J7: =I7*EXP((Inputs!$B$6-Inputs!$B$7-0.5*Inputs!$B$8^2)*$B$2+Inputs!$B$8*SQRT($B$2)*MC_Shocks!H4) -> 557.11654 | ... BM7: =BL7*EXP((Inputs!$B$6-Inputs!$B$7-0.5*Inputs!$B$8^2)*$B$2+Inputs!$B$8*SQRT($B$2)*MC_Shocks!BK4) -> 587.83022 | BN7: =AVERAGE(C7:BM7) -> 565.55888 | BO7: =MAX(B7:BM7) -> 593.95347 | BP7: =MAX(BM7-Inputs!$B$4,0) -> 12.830215 | BQ7: =MAX(Inputs!$B$4-BM7,0) -> 0 | BR7: =MAX(BN7-Inputs!$B$4,0) -> 0 | BS7: =IF(BO7>=Inputs!$B$9,0,MAX(BM7-Inputs!$B$4,0)) -> 12.830215
A8: 4 | B8: =Inputs!$B$3 -> 574.78802 | C8: =B8*EXP((Inputs!$B$6-Inputs!$B$7-0.5*Inputs!$B$8^2)*$B$2+Inputs!$B$8*SQRT($B$2)*MC_Shocks!A5) -> 567.97558 | D8: =C8*EXP((Inputs!$B$6-Inputs!$B$7-0.5*Inputs!$B$8^2)*$B$2+Inputs!$B$8*SQRT($B$2)*MC_Shocks!B5) -> 566.02065 | E8: =D8*EXP((Inputs!$B$6-Inputs!$B$7-0.5*Inputs!$B$8^2)*$B$2+Inputs!$B$8*SQRT($B$2)*MC_Shocks!C5) -> 569.93292 | F8: =E8*EXP((Inputs!$B$6-Inputs!$B$7-0.5*Inputs!$B$8^2)*$B$2+Inputs!$B$8*SQRT($B$2)*MC_Shocks!D5) -> 570.95557 | G8: =F8*EXP((Inputs!$B$6-Inputs!$B$7-0.5*Inputs!$B$8^2)*$B$2+Inputs!$B$8*SQRT($B$2)*MC_Shocks!E5) -> 565.39428 | H8: =G8*EXP((Inputs!$B$6-Inputs!$B$7-0.5*Inputs!$B$8^2)*$B$2+Inputs!$B$8*SQRT($B$2)*MC_Shocks!F5) -> 566.22498 | I8: =H8*EXP((Inputs!$B$6-Inputs!$B$7-0.5*Inputs!$B$8^2)*$B$2+Inputs!$B$8*SQRT($B$2)*MC_Shocks!G5) -> 568.01199 | J8: =I8*EXP((Inputs!$B$6-Inputs!$B$7-0.5*Inputs!$B$8^2)*$B$2+Inputs!$B$8*SQRT($B$2)*MC_Shocks!H5) -> 564.09645 | ... BM8: =BL8*EXP((Inputs!$B$6-Inputs!$B$7-0.5*Inputs!$B$8^2)*$B$2+Inputs!$B$8*SQRT($B$2)*MC_Shocks!BK5) -> 595.96856 | BN8: =AVERAGE(C8:BM8) -> 587.62805 | BO8: =MAX(B8:BM8) -> 611.38599 | BP8: =MAX(BM8-Inputs!$B$4,0) -> 20.968559 | BQ8: =MAX(Inputs!$B$4-BM8,0) -> 0 | BR8: =MAX(BN8-Inputs!$B$4,0) -> 12.628055 | BS8: =IF(BO8>=Inputs!$B$9,0,MAX(BM8-Inputs!$B$4,0)) -> 0
A9: 5 | B9: =Inputs!$B$3 -> 574.78802 | C9: =B9*EXP((Inputs!$B$6-Inputs!$B$7-0.5*Inputs!$B$8^2)*$B$2+Inputs!$B$8*SQRT($B$2)*MC_Shocks!A6) -> 584.60162 | D9: =C9*EXP((Inputs!$B$6-Inputs!$B$7-0.5*Inputs!$B$8^2)*$B$2+Inputs!$B$8*SQRT($B$2)*MC_Shocks!B6) -> 589.46507 | E9: =D9*EXP((Inputs!$B$6-Inputs!$B$7-0.5*Inputs!$B$8^2)*$B$2+Inputs!$B$8*SQRT($B$2)*MC_Shocks!C6) -> 582.45777 | F9: =E9*EXP((Inputs!$B$6-Inputs!$B$7-0.5*Inputs!$B$8^2)*$B$2+Inputs!$B$8*SQRT($B$2)*MC_Shocks!D6) -> 580.27934 | G9: =F9*EXP((Inputs!$B$6-Inputs!$B$7-0.5*Inputs!$B$8^2)*$B$2+Inputs!$B$8*SQRT($B$2)*MC_Shocks!E6) -> 586.19605 | H9: =G9*EXP((Inputs!$B$6-Inputs!$B$7-0.5*Inputs!$B$8^2)*$B$2+Inputs!$B$8*SQRT($B$2)*MC_Shocks!F6) -> 582.9694 | I9: =H9*EXP((Inputs!$B$6-Inputs!$B$7-0.5*Inputs!$B$8^2)*$B$2+Inputs!$B$8*SQRT($B$2)*MC_Shocks!G6) -> 585.08073 | J9: =I9*EXP((Inputs!$B$6-Inputs!$B$7-0.5*Inputs!$B$8^2)*$B$2+Inputs!$B$8*SQRT($B$2)*MC_Shocks!H6) -> 588.74273 | ... BM9: =BL9*EXP((Inputs!$B$6-Inputs!$B$7-0.5*Inputs!$B$8^2)*$B$2+Inputs!$B$8*SQRT($B$2)*MC_Shocks!BK6) -> 597.8302 | BN9: =AVERAGE(C9:BM9) -> 570.75662 | BO9: =MAX(B9:BM9) -> 597.8302 | BP9: =MAX(BM9-Inputs!$B$4,0) -> 22.830201 | BQ9: =MAX(Inputs!$B$4-BM9,0) -> 0 | BR9: =MAX(BN9-Inputs!$B$4,0) -> 0 | BS9: =IF(BO9>=Inputs!$B$9,0,MAX(BM9-Inputs!$B$4,0)) -> 22.830201
A10: 6 | B10: =Inputs!$B$3 -> 574.78802 | C10: =B10*EXP((Inputs!$B$6-Inputs!$B$7-0.5*Inputs!$B$8^2)*$B$2+Inputs!$B$8*SQRT($B$2)*MC_Shocks!A7) -> 574.93804 | D10: =C10*EXP((Inputs!$B$6-Inputs!$B$7-0.5*Inputs!$B$8^2)*$B$2+Inputs!$B$8*SQRT($B$2)*MC_Shocks!B7) -> 578.11135 | E10: =D10*EXP((Inputs!$B$6-Inputs!$B$7-0.5*Inputs!$B$8^2)*$B$2+Inputs!$B$8*SQRT($B$2)*MC_Shocks!C7) -> 576.74458 | F10: =E10*EXP((Inputs!$B$6-Inputs!$B$7-0.5*Inputs!$B$8^2)*$B$2+Inputs!$B$8*SQRT($B$2)*MC_Shocks!D7) -> 578.28419 | G10: =F10*EXP((Inputs!$B$6-Inputs!$B$7-0.5*Inputs!$B$8^2)*$B$2+Inputs!$B$8*SQRT($B$2)*MC_Shocks!E7) -> 577.74196 | H10: =G10*EXP((Inputs!$B$6-Inputs!$B$7-0.5*Inputs!$B$8^2)*$B$2+Inputs!$B$8*SQRT($B$2)*MC_Shocks!F7) -> 578.24123 | I10: =H10*EXP((Inputs!$B$6-Inputs!$B$7-0.5*Inputs!$B$8^2)*$B$2+Inputs!$B$8*SQRT($B$2)*MC_Shocks!G7) -> 581.03257 | J10: =I10*EXP((Inputs!$B$6-Inputs!$B$7-0.5*Inputs!$B$8^2)*$B$2+Inputs!$B$8*SQRT($B$2)*MC_Shocks!H7) -> 577.32781 | ... BM10: =BL10*EXP((Inputs!$B$6-Inputs!$B$7-0.5*Inputs!$B$8^2)*$B$2+Inputs!$B$8*SQRT($B$2)*MC_Shocks!BK7) -> 601.17139 | BN10: =AVERAGE(C10:BM10) -> 579.46729 | BO10: =MAX(B10:BM10) -> 601.17139 | BP10: =MAX(BM10-Inputs!$B$4,0) -> 26.171395 | BQ10: =MAX(Inputs!$B$4-BM10,0) -> 0 | BR10: =MAX(BN10-Inputs!$B$4,0) -> 4.4672897 | BS10: =IF(BO10>=Inputs!$B$9,0,MAX(BM10-Inputs!$B$4,0)) -> 26.171395
A11: 7 | B11: =Inputs!$B$3 -> 574.78802 | C11: =B11*EXP((Inputs!$B$6-Inputs!$B$7-0.5*Inputs!$B$8^2)*$B$2+Inputs!$B$8*SQRT($B$2)*MC_Shocks!A8) -> 584.91543 | D11: =C11*EXP((Inputs!$B$6-Inputs!$B$7-0.5*Inputs!$B$8^2)*$B$2+Inputs!$B$8*SQRT($B$2)*MC_Shocks!B8) -> 581.23166 | E11: =D11*EXP((Inputs!$B$6-Inputs!$B$7-0.5*Inputs!$B$8^2)*$B$2+Inputs!$B$8*SQRT($B$2)*MC_Shocks!C8) -> 577.42713 | F11: =E11*EXP((Inputs!$B$6-Inputs!$B$7-0.5*Inputs!$B$8^2)*$B$2+Inputs!$B$8*SQRT($B$2)*MC_Shocks!D8) -> 574.74221 | G11: =F11*EXP((Inputs!$B$6-Inputs!$B$7-0.5*Inputs!$B$8^2)*$B$2+Inputs!$B$8*SQRT($B$2)*MC_Shocks!E8) -> 565.19294 | H11: =G11*EXP((Inputs!$B$6-Inputs!$B$7-0.5*Inputs!$B$8^2)*$B$2+Inputs!$B$8*SQRT($B$2)*MC_Shocks!F8) -> 562.89364 | I11: =H11*EXP((Inputs!$B$6-Inputs!$B$7-0.5*Inputs!$B$8^2)*$B$2+Inputs!$B$8*SQRT($B$2)*MC_Shocks!G8) -> 559.56677 | J11: =I11*EXP((Inputs!$B$6-Inputs!$B$7-0.5*Inputs!$B$8^2)*$B$2+Inputs!$B$8*SQRT($B$2)*MC_Shocks!H8) -> 560.28761 | ... BM11: =BL11*EXP((Inputs!$B$6-Inputs!$B$7-0.5*Inputs!$B$8^2)*$B$2+Inputs!$B$8*SQRT($B$2)*MC_Shocks!BK8) -> 593.96368 | BN11: =AVERAGE(C11:BM11) -> 579.78271 | BO11: =MAX(B11:BM11) -> 612.8232 | BP11: =MAX(BM11-Inputs!$B$4,0) -> 18.963681 | BQ11: =MAX(Inputs!$B$4-BM11,0) -> 0 | BR11: =MAX(BN11-Inputs!$B$4,0) -> 4.7827132 | BS11: =IF(BO11>=Inputs!$B$9,0,MAX(BM11-Inputs!$B$4,0)) -> 0
A12: 8 | B12: =Inputs!$B$3 -> 574.78802 | C12: =B12*EXP((Inputs!$B$6-Inputs!$B$7-0.5*Inputs!$B$8^2)*$B$2+Inputs!$B$8*SQRT($B$2)*MC_Shocks!A9) -> 574.69317 | D12: =C12*EXP((Inputs!$B$6-Inputs!$B$7-0.5*Inputs!$B$8^2)*$B$2+Inputs!$B$8*SQRT($B$2)*MC_Shocks!B9) -> 565.39787 | E12: =D12*EXP((Inputs!$B$6-Inputs!$B$7-0.5*Inputs!$B$8^2)*$B$2+Inputs!$B$8*SQRT($B$2)*MC_Shocks!C9) -> 565.05158 | F12: =E12*EXP((Inputs!$B$6-Inputs!$B$7-0.5*Inputs!$B$8^2)*$B$2+Inputs!$B$8*SQRT($B$2)*MC_Shocks!D9) -> 559.28716 | G12: =F12*EXP((Inputs!$B$6-Inputs!$B$7-0.5*Inputs!$B$8^2)*$B$2+Inputs!$B$8*SQRT($B$2)*MC_Shocks!E9) -> 562.31931 | H12: =G12*EXP((Inputs!$B$6-Inputs!$B$7-0.5*Inputs!$B$8^2)*$B$2+Inputs!$B$8*SQRT($B$2)*MC_Shocks!F9) -> 564.01023 | I12: =H12*EXP((Inputs!$B$6-Inputs!$B$7-0.5*Inputs!$B$8^2)*$B$2+Inputs!$B$8*SQRT($B$2)*MC_Shocks!G9) -> 559.8734 | J12: =I12*EXP((Inputs!$B$6-Inputs!$B$7-0.5*Inputs!$B$8^2)*$B$2+Inputs!$B$8*SQRT($B$2)*MC_Shocks!H9) -> 557.64833 | ... BM12: =BL12*EXP((Inputs!$B$6-Inputs!$B$7-0.5*Inputs!$B$8^2)*$B$2+Inputs!$B$8*SQRT($B$2)*MC_Shocks!BK9) -> 550.7527 | BN12: =AVERAGE(C12:BM12) -> 548.76229 | BO12: =MAX(B12:BM12) -> 574.78802 | BP12: =MAX(BM12-Inputs!$B$4,0) -> 0 | BQ12: =MAX(Inputs!$B$4-BM12,0) -> 24.2473 | BR12: =MAX(BN12-Inputs!$B$4,0) -> 0 | BS12: =IF(BO12>=Inputs!$B$9,0,MAX(BM12-Inputs!$B$4,0)) -> 0
A13: 9 | B13: =Inputs!$B$3 -> 574.78802 | C13: =B13*EXP((Inputs!$B$6-Inputs!$B$7-0.5*Inputs!$B$8^2)*$B$2+Inputs!$B$8*SQRT($B$2)*MC_Shocks!A10) -> 571.88283 | D13: =C13*EXP((Inputs!$B$6-Inputs!$B$7-0.5*Inputs!$B$8^2)*$B$2+Inputs!$B$8*SQRT($B$2)*MC_Shocks!B10) -> 569.73088 | E13: =D13*EXP((Inputs!$B$6-Inputs!$B$7-0.5*Inputs!$B$8^2)*$B$2+Inputs!$B$8*SQRT($B$2)*MC_Shocks!C10) -> 567.11324 | F13: =E13*EXP((Inputs!$B$6-Inputs!$B$7-0.5*Inputs!$B$8^2)*$B$2+Inputs!$B$8*SQRT($B$2)*MC_Shocks!D10) -> 563.29266 | G13: =F13*EXP((Inputs!$B$6-Inputs!$B$7-0.5*Inputs!$B$8^2)*$B$2+Inputs!$B$8*SQRT($B$2)*MC_Shocks!E10) -> 563.56268 | H13: =G13*EXP((Inputs!$B$6-Inputs!$B$7-0.5*Inputs!$B$8^2)*$B$2+Inputs!$B$8*SQRT($B$2)*MC_Shocks!F10) -> 559.91277 | I13: =H13*EXP((Inputs!$B$6-Inputs!$B$7-0.5*Inputs!$B$8^2)*$B$2+Inputs!$B$8*SQRT($B$2)*MC_Shocks!G10) -> 561.16829 | J13: =I13*EXP((Inputs!$B$6-Inputs!$B$7-0.5*Inputs!$B$8^2)*$B$2+Inputs!$B$8*SQRT($B$2)*MC_Shocks!H10) -> 560.99761 | ... BM13: =BL13*EXP((Inputs!$B$6-Inputs!$B$7-0.5*Inputs!$B$8^2)*$B$2+Inputs!$B$8*SQRT($B$2)*MC_Shocks!BK10) -> 521.83257 | BN13: =AVERAGE(C13:BM13) -> 534.27553 | BO13: =MAX(B13:BM13) -> 574.78802 | BP13: =MAX(BM13-Inputs!$B$4,0) -> 0 | BQ13: =MAX(Inputs!$B$4-BM13,0) -> 53.167428 | BR13: =MAX(BN13-Inputs!$B$4,0) -> 0 | BS13: =IF(BO13>=Inputs!$B$9,0,MAX(BM13-Inputs!$B$4,0)) -> 0
A14: 10 | B14: =Inputs!$B$3 -> 574.78802 | C14: =B14*EXP((Inputs!$B$6-Inputs!$B$7-0.5*Inputs!$B$8^2)*$B$2+Inputs!$B$8*SQRT($B$2)*MC_Shocks!A11) -> 570.2635 | D14: =C14*EXP((Inputs!$B$6-Inputs!$B$7-0.5*Inputs!$B$8^2)*$B$2+Inputs!$B$8*SQRT($B$2)*MC_Shocks!B11) -> 561.91576 | E14: =D14*EXP((Inputs!$B$6-Inputs!$B$7-0.5*Inputs!$B$8^2)*$B$2+Inputs!$B$8*SQRT($B$2)*MC_Shocks!C11) -> 560.40388 | F14: =E14*EXP((Inputs!$B$6-Inputs!$B$7-0.5*Inputs!$B$8^2)*$B$2+Inputs!$B$8*SQRT($B$2)*MC_Shocks!D11) -> 560.53864 | G14: =F14*EXP((Inputs!$B$6-Inputs!$B$7-0.5*Inputs!$B$8^2)*$B$2+Inputs!$B$8*SQRT($B$2)*MC_Shocks!E11) -> 568.09668 | H14: =G14*EXP((Inputs!$B$6-Inputs!$B$7-0.5*Inputs!$B$8^2)*$B$2+Inputs!$B$8*SQRT($B$2)*MC_Shocks!F11) -> 569.62568 | I14: =H14*EXP((Inputs!$B$6-Inputs!$B$7-0.5*Inputs!$B$8^2)*$B$2+Inputs!$B$8*SQRT($B$2)*MC_Shocks!G11) -> 568.6901 | J14: =I14*EXP((Inputs!$B$6-Inputs!$B$7-0.5*Inputs!$B$8^2)*$B$2+Inputs!$B$8*SQRT($B$2)*MC_Shocks!H11) -> 572.49822 | ... BM14: =BL14*EXP((Inputs!$B$6-Inputs!$B$7-0.5*Inputs!$B$8^2)*$B$2+Inputs!$B$8*SQRT($B$2)*MC_Shocks!BK11) -> 622.70721 | BN14: =AVERAGE(C14:BM14) -> 583.67176 | BO14: =MAX(B14:BM14) -> 624.77175 | BP14: =MAX(BM14-Inputs!$B$4,0) -> 47.707213 | BQ14: =MAX(Inputs!$B$4-BM14,0) -> 0 | BR14: =MAX(BN14-Inputs!$B$4,0) -> 8.6717604 | BS14: =IF(BO14>=Inputs!$B$9,0,MAX(BM14-Inputs!$B$4,0)) -> 0
A15: 11 | B15: =Inputs!$B$3 -> 574.78802 | C15: =B15*EXP((Inputs!$B$6-Inputs!$B$7-0.5*Inputs!$B$8^2)*$B$2+Inputs!$B$8*SQRT($B$2)*MC_Shocks!A12) -> 567.17585 | D15: =C15*EXP((Inputs!$B$6-Inputs!$B$7-0.5*Inputs!$B$8^2)*$B$2+Inputs!$B$8*SQRT($B$2)*MC_Shocks!B12) -> 574.15396 | E15: =D15*EXP((Inputs!$B$6-Inputs!$B$7-0.5*Inputs!$B$8^2)*$B$2+Inputs!$B$8*SQRT($B$2)*MC_Shocks!C12) -> 573.48882 | F15: =E15*EXP((Inputs!$B$6-Inputs!$B$7-0.5*Inputs!$B$8^2)*$B$2+Inputs!$B$8*SQRT($B$2)*MC_Shocks!D12) -> 571.60394 | G15: =F15*EXP((Inputs!$B$6-Inputs!$B$7-0.5*Inputs!$B$8^2)*$B$2+Inputs!$B$8*SQRT($B$2)*MC_Shocks!E12) -> 567.0864 | H15: =G15*EXP((Inputs!$B$6-Inputs!$B$7-0.5*Inputs!$B$8^2)*$B$2+Inputs!$B$8*SQRT($B$2)*MC_Shocks!F12) -> 559.74319 | I15: =H15*EXP((Inputs!$B$6-Inputs!$B$7-0.5*Inputs!$B$8^2)*$B$2+Inputs!$B$8*SQRT($B$2)*MC_Shocks!G12) -> 563.46353 | J15: =I15*EXP((Inputs!$B$6-Inputs!$B$7-0.5*Inputs!$B$8^2)*$B$2+Inputs!$B$8*SQRT($B$2)*MC_Shocks!H12) -> 563.84453 | ... BM15: =BL15*EXP((Inputs!$B$6-Inputs!$B$7-0.5*Inputs!$B$8^2)*$B$2+Inputs!$B$8*SQRT($B$2)*MC_Shocks!BK12) -> 541.59778 | BN15: =AVERAGE(C15:BM15) -> 549.01298 | BO15: =MAX(B15:BM15) -> 574.78802 | BP15: =MAX(BM15-Inputs!$B$4,0) -> 0 | BQ15: =MAX(Inputs!$B$4-BM15,0) -> 33.40222 | BR15: =MAX(BN15-Inputs!$B$4,0) -> 0 | BS15: =IF(BO15>=Inputs!$B$9,0,MAX(BM15-Inputs!$B$4,0)) -> 0
A16: 12 | B16: =Inputs!$B$3 -> 574.78802 | C16: =B16*EXP((Inputs!$B$6-Inputs!$B$7-0.5*Inputs!$B$8^2)*$B$2+Inputs!$B$8*SQRT($B$2)*MC_Shocks!A13) -> 577.65791 | D16: =C16*EXP((Inputs!$B$6-Inputs!$B$7-0.5*Inputs!$B$8^2)*$B$2+Inputs!$B$8*SQRT($B$2)*MC_Shocks!B13) -> 580.43697 | E16: =D16*EXP((Inputs!$B$6-Inputs!$B$7-0.5*Inputs!$B$8^2)*$B$2+Inputs!$B$8*SQRT($B$2)*MC_Shocks!C13) -> 579.06801 | F16: =E16*EXP((Inputs!$B$6-Inputs!$B$7-0.5*Inputs!$B$8^2)*$B$2+Inputs!$B$8*SQRT($B$2)*MC_Shocks!D13) -> 580.62288 | G16: =F16*EXP((Inputs!$B$6-Inputs!$B$7-0.5*Inputs!$B$8^2)*$B$2+Inputs!$B$8*SQRT($B$2)*MC_Shocks!E13) -> 574.94291 | H16: =G16*EXP((Inputs!$B$6-Inputs!$B$7-0.5*Inputs!$B$8^2)*$B$2+Inputs!$B$8*SQRT($B$2)*MC_Shocks!F13) -> 579.22751 | I16: =H16*EXP((Inputs!$B$6-Inputs!$B$7-0.5*Inputs!$B$8^2)*$B$2+Inputs!$B$8*SQRT($B$2)*MC_Shocks!G13) -> 578.43307 | J16: =I16*EXP((Inputs!$B$6-Inputs!$B$7-0.5*Inputs!$B$8^2)*$B$2+Inputs!$B$8*SQRT($B$2)*MC_Shocks!H13) -> 576.09377 | ... BM16: =BL16*EXP((Inputs!$B$6-Inputs!$B$7-0.5*Inputs!$B$8^2)*$B$2+Inputs!$B$8*SQRT($B$2)*MC_Shocks!BK13) -> 544.75618 | BN16: =AVERAGE(C16:BM16) -> 563.57476 | BO16: =MAX(B16:BM16) -> 580.96268 | BP16: =MAX(BM16-Inputs!$B$4,0) -> 0 | BQ16: =MAX(Inputs!$B$4-BM16,0) -> 30.243824 | BR16: =MAX(BN16-Inputs!$B$4,0) -> 0 | BS16: =IF(BO16>=Inputs!$B$9,0,MAX(BM16-Inputs!$B$4,0)) -> 0
... A504: 500 | B504: =Inputs!$B$3 -> 574.78802 | C504: =B504*EXP((Inputs!$B$6-Inputs!$B$7-0.5*Inputs!$B$8^2)*$B$2+Inputs!$B$8*SQRT($B$2)*MC_Shocks!A501) -> 573.50426 | D504: =C504*EXP((Inputs!$B$6-Inputs!$B$7-0.5*Inputs!$B$8^2)*$B$2+Inputs!$B$8*SQRT($B$2)*MC_Shocks!B501) -> 572.07426 | E504: =D504*EXP((Inputs!$B$6-Inputs!$B$7-0.5*Inputs!$B$8^2)*$B$2+Inputs!$B$8*SQRT($B$2)*MC_Shocks!C501) -> 574.46274 | F504: =E504*EXP((Inputs!$B$6-Inputs!$B$7-0.5*Inputs!$B$8^2)*$B$2+Inputs!$B$8*SQRT($B$2)*MC_Shocks!D501) -> 570.95606 | G504: =F504*EXP((Inputs!$B$6-Inputs!$B$7-0.5*Inputs!$B$8^2)*$B$2+Inputs!$B$8*SQRT($B$2)*MC_Shocks!E501) -> 577.37827 | H504: =G504*EXP((Inputs!$B$6-Inputs!$B$7-0.5*Inputs!$B$8^2)*$B$2+Inputs!$B$8*SQRT($B$2)*MC_Shocks!F501) -> 578.55336 | I504: =H504*EXP((Inputs!$B$6-Inputs!$B$7-0.5*Inputs!$B$8^2)*$B$2+Inputs!$B$8*SQRT($B$2)*MC_Shocks!G501) -> 576.06212 | J504: =I504*EXP((Inputs!$B$6-Inputs!$B$7-0.5*Inputs!$B$8^2)*$B$2+Inputs!$B$8*SQRT($B$2)*MC_Shocks!H501) -> 577.43231 | ... BM504: =BL504*EXP((Inputs!$B$6-Inputs!$B$7-0.5*Inputs!$B$8^2)*$B$2+Inputs!$B$8*SQRT($B$2)*MC_Shocks!BK501) -> 609.56975 | BN504: =AVERAGE(C504:BM504) -> 597.76297 | BO504: =MAX(B504:BM504) -> 630.34479 | BP504: =MAX(BM504-Inputs!$B$4,0) -> 34.569754 | BQ504: =MAX(Inputs!$B$4-BM504,0) -> 0 | BR504: =MAX(BN504-Inputs!$B$4,0) -> 22.762971 | BS504: =IF(BO504>=Inputs!$B$9,0,MAX(BM504-Inputs!$B$4,0)) -> 0

Sheet Correlated_GBM
A1: Two correlated GBM paths (SPY and JPM) using a Cholesky factor of the realized 2024 correlation
A2: Correlation (daily log returns) | B2: =CORREL(Data!D3:D253,Data!E3:E253) -> 0.43116774
A3: Cholesky L21 | B3: =B2 -> 0.43116774
A4: Cholesky L22 | B4: =SQRT(1-B2^2) -> 0.90227179
A5: JPM sigma (annualized) | B5: =STDEV(Data!E3:E253)*SQRT(252) -> 0.23344727
A6: JPM spot | B6: =Data!C253 -> 231.45416
A7: dt | B7: =Inputs!B5/Inputs!B11 -> 0.003968254
A9: step | B9: z1 | C9: z2 | D9: Correlated shock 1 | E9: Correlated shock 2 | F9: SPY path | G9: JPM path
A10: 0 | F10: =Inputs!B3 -> 574.78802 | G10: =B6 -> 231.45416
A11: 1 | B11: 1.0759341 | C11: 0.14575864 | D11: =B11 -> 1.0759341 | E11: =$B$3*B11+$B$4*C11 -> 0.59542199 | F11: =F10*EXP((Inputs!$B$6-Inputs!$B$7-0.5*Inputs!$B$8^2)*$B$7+Inputs!$B$8*SQRT($B$7)*D11) -> 579.76972 | G11: =G10*EXP((Inputs!$B$6-0.5*$B$5^2)*$B$7+$B$5*SQRT($B$7)*E11) -> 233.50495
A12: 2 | B12: 0.51155553 | C12: 0.36543184 | D12: =B12 -> 0.51155553 | E12: =$B$3*B12+$B$4*C12 -> 0.55028508 | F12: =F11*EXP((Inputs!$B$6-Inputs!$B$7-0.5*Inputs!$B$8^2)*$B$7+Inputs!$B$8*SQRT($B$7)*D12) -> 582.18221 | G12: =G11*EXP((Inputs!$B$6-0.5*$B$5^2)*$B$7+$B$5*SQRT($B$7)*E12) -> 235.4176
A13: 3 | B13: -0.12148711 | C13: -0.86000248 | D13: =B13 -> -0.12148711 | E13: =$B$3*B13+$B$4*C13 -> -0.82833729 | F13: =F12*EXP((Inputs!$B$6-Inputs!$B$7-0.5*Inputs!$B$8^2)*$B$7+Inputs!$B$8*SQRT($B$7)*D13) -> 581.67626 | G13: =G12*EXP((Inputs!$B$6-0.5*$B$5^2)*$B$7+$B$5*SQRT($B$7)*E13) -> 232.58247
A14: 4 | B14: -0.082136664 | C14: 0.98676162 | D14: =B14 -> -0.082136664 | E14: =$B$3*B14+$B$4*C14 -> 0.85491249 | F14: =F13*EXP((Inputs!$B$6-Inputs!$B$7-0.5*Inputs!$B$8^2)*$B$7+Inputs!$B$8*SQRT($B$7)*D14) -> 581.35221 | G14: =G13*EXP((Inputs!$B$6-0.5*$B$5^2)*$B$7+$B$5*SQRT($B$7)*E14) -> 235.54037
A15: 5 | B15: -0.44147581 | C15: 0.89334726 | D15: =B15 -> -0.44147581 | E15: =$B$3*B15+$B$4*C15 -> 0.61569191 | F15: =F14*EXP((Inputs!$B$6-Inputs!$B$7-0.5*Inputs!$B$8^2)*$B$7+Inputs!$B$8*SQRT($B$7)*D15) -> 579.3744 | G15: =G14*EXP((Inputs!$B$6-0.5*$B$5^2)*$B$7+$B$5*SQRT($B$7)*E15) -> 237.69821
A16: 6 | B16: 0.73707067 | C16: -0.2989374 | D16: =B16 -> 0.73707067 | E16: =$B$3*B16+$B$4*C16 -> 0.048078315 | F16: =F15*EXP((Inputs!$B$6-Inputs!$B$7-0.5*Inputs!$B$8^2)*$B$7+Inputs!$B$8*SQRT($B$7)*D16) -> 582.82699 | G16: =G15*EXP((Inputs!$B$6-0.5*$B$5^2)*$B$7+$B$5*SQRT($B$7)*E16) -> 237.88186
A17: 7 | B17: 1.3888001 | C17: -0.35554667 | D17: =B17 -> 1.3888001 | E17: =$B$3*B17+$B$4*C17 -> 0.27800607 | F17: =F16*EXP((Inputs!$B$6-Inputs!$B$7-0.5*Inputs!$B$8^2)*$B$7+Inputs!$B$8*SQRT($B$7)*D17) -> 589.33926 | G17: =G16*EXP((Inputs!$B$6-0.5*$B$5^2)*$B$7+$B$5*SQRT($B$7)*E17) -> 238.87198
A18: 8 | B18: 1.5095469 | C18: 0.43412698 | D18: =B18 -> 1.5095469 | E18: =$B$3*B18+$B$4*C18 -> 1.0425684 | F18: =F17*EXP((Inputs!$B$6-Inputs!$B$7-0.5*Inputs!$B$8^2)*$B$7+Inputs!$B$8*SQRT($B$7)*D18) -> 596.49539 | G18: =G17*EXP((Inputs!$B$6-0.5*$B$5^2)*$B$7+$B$5*SQRT($B$7)*E18) -> 242.57837
