Workbook

Sheet Summary
A1: 1-day VaR summary (USD, 1,000,000 portfolio)
A3: Confidence | B3: Variance-covariance | C3: Historical simulation | D3: Monte Carlo
A4: 0.99 | B4: =Parametric!C11 -> 31215.576 | C4: =Historical!C4 -> 31363.023 | D4: =MonteCarlo!B8 -> 29875.331
A5: 0.95 | B5: =Parametric!C12 -> 22071.099 | C5: =Historical!C5 -> 19926.395 | D5: =MonteCarlo!B9 -> 19594.881
A6: 0.9 | B6: =Parametric!C13 -> 17196.212 | C6: =Historical!C6 -> 11828.857 | D6: =MonteCarlo!B10 -> 15355.635
A8: 99% backtest (250 days) | B8: Historical | C8: Parametric
A9: Exceptions | B9: =Backtest!I5 -> 4 | C9: =Backtest!J5 -> 4
A10: Expected | B10: =Backtest!I6 -> 2.5 | C10: =Backtest!J6 -> 2.5
A11: Kupiec LR | B11: =Backtest!I7 -> 0.76913836 | C11: =Backtest!J7 -> 0.76913836
A12: Kupiec result | B12: =Backtest!I9 -> Do not reject | C12: =Backtest!J9 -> Do not reject
A13: Basel zone | B13: =Backtest!I10 -> Green | C13: =Backtest!J10 -> Green

Sheet Inputs
A1: Market risk VaR engine: inputs
A2: Portfolio notional (USD) | B2: 1000000
A3: Weights | B3: JPM | C3: MS | D3: BAC
A4: Weight | B4: 0.4 | C4: 0.3 | D4: 0.3
A5: Weights sum check | B5: =SUM(B4:D4) -> 1
A6: Estimation window (days) | B6: 250
A8: Data: Yahoo Finance adjusted closes. Log returns. Portfolio weights are held constant (daily rebalanced).
A9: Parametric and Monte Carlo VaR assume zero mean. Latest window = most recent 250 returns.

Sheet Prices
A1: Date | B1: JPM | C1: MS | D1: BAC
A2: 44930 | B2: 124.88905 | C2: 77.024689 | D2: 31.058544
A3: 44931 | B3: 124.86135 | C3: 76.375786 | D3: 30.994867
A4: 44932 | B4: 127.25063 | C4: 77.833603 | D4: 31.304173
A5: 44935 | B5: 126.72481 | C5: 77.904732 | D5: 30.831104
A6: 44936 | B6: 127.85951 | C6: 79.042534 | D6: 31.040358
A7: 44937 | B7: 128.80969 | C7: 79.495888 | D7: 31.276884
A8: 44938 | B8: 128.68056 | C8: 80.473686 | D8: 31.358759
A9: 44939 | B9: 131.92775 | C9: 81.47818 | D9: 32.050171
A10: 44943 | B10: 129.88904 | C10: 86.29612 | D10: 31.404251
A11: 44944 | B11: 125.98681 | C11: 85.851646 | D11: 30.676455
A12: 44945 | B12: 124.30785 | C12: 83.691582 | D12: 30.230684
A13: 44946 | B13: 124.61226 | C13: 85.549408 | D13: 30.794714
... A502: 45657 | B502: 231.45415 | C502: 120.3127 | D502: 42.277176

Sheet Returns
A1: Date | B1: JPM log ret | C1: MS log ret | D1: BAC log ret | E1: Portfolio return | F1: Portfolio P&L (USD)
A2: =Prices!A3 -> 44931 | B2: =LN(Prices!B3/Prices!B2) -> -0.00022177905 | C2: =LN(Prices!C3/Prices!C2) -> -0.0084602967 | D2: =LN(Prices!D3/Prices!D2) -> -0.0020523241 | E2: =SUMPRODUCT(B2:D2,Inputs!$B$4:$D$4) -> -0.0032424979 | F2: =E2*Inputs!$B$2 -> -3242.4979
A3: =Prices!A4 -> 44932 | B3: =LN(Prices!B4/Prices!B3) -> 0.018954702 | C3: =LN(Prices!C4/Prices!C3) -> 0.018907545 | D3: =LN(Prices!D4/Prices!D3) -> 0.0099297753 | E3: =SUMPRODUCT(B3:D3,Inputs!$B$4:$D$4) -> 0.016233077 | F3: =E3*Inputs!$B$2 -> 16233.077
A4: =Prices!A5 -> 44935 | B4: =LN(Prices!B5/Prices!B4) -> -0.0041407646 | C4: =LN(Prices!C5/Prices!C4) -> 0.00091344049 | D4: =LN(Prices!D5/Prices!D4) -> -0.015227336 | E4: =SUMPRODUCT(B4:D4,Inputs!$B$4:$D$4) -> -0.0059504746 | F4: =E4*Inputs!$B$2 -> -5950.4746
A5: =Prices!A6 -> 44936 | B5: =LN(Prices!B6/Prices!B5) -> 0.008914234 | C5: =LN(Prices!C6/Prices!C5) -> 0.014499419 | D5: =LN(Prices!D6/Prices!D5) -> 0.006764156 | E5: =SUMPRODUCT(B5:D5,Inputs!$B$4:$D$4) -> 0.009944766 | F5: =E5*Inputs!$B$2 -> 9944.766
A6: =Prices!A7 -> 44937 | B6: =LN(Prices!B7/Prices!B6) -> 0.007403961 | C6: =LN(Prices!C7/Prices!C6) -> 0.0057191829 | D6: =LN(Prices!D7/Prices!D6) -> 0.0075910813 | E6: =SUMPRODUCT(B6:D6,Inputs!$B$4:$D$4) -> 0.0069546637 | F6: =E6*Inputs!$B$2 -> 6954.6637
A7: =Prices!A8 -> 44938 | B7: =LN(Prices!B8/Prices!B7) -> -0.0010030294 | C7: =LN(Prices!C8/Prices!C7) -> 0.012224958 | D7: =LN(Prices!D8/Prices!D7) -> 0.0026143228 | E7: =SUMPRODUCT(B7:D7,Inputs!$B$4:$D$4) -> 0.0040505724 | F7: =E7*Inputs!$B$2 -> 4050.5724
A8: =Prices!A9 -> 44939 | B8: =LN(Prices!B9/Prices!B8) -> 0.024921389 | C8: =LN(Prices!C9/Prices!C8) -> 0.012405002 | D8: =LN(Prices!D9/Prices!D8) -> 0.021808896 | E8: =SUMPRODUCT(B8:D8,Inputs!$B$4:$D$4) -> 0.020232725 | F8: =E8*Inputs!$B$2 -> 20232.725
A9: =Prices!A10 -> 44943 | B9: =LN(Prices!B10/Prices!B9) -> -0.015573889 | C9: =LN(Prices!C10/Prices!C9) -> 0.057449381 | D9: =LN(Prices!D10/Prices!D9) -> -0.020359247 | E9: =SUMPRODUCT(B9:D9,Inputs!$B$4:$D$4) -> 0.0048974847 | F9: =E9*Inputs!$B$2 -> 4897.4847
A10: =Prices!A11 -> 44944 | B10: =LN(Prices!B11/Prices!B10) -> -0.030503324 | C10: =LN(Prices!C11/Prices!C10) -> -0.005163869 | D10: =LN(Prices!D11/Prices!D10) -> -0.023447862 | E10: =SUMPRODUCT(B10:D10,Inputs!$B$4:$D$4) -> -0.020784849 | F10: =E10*Inputs!$B$2 -> -20784.849
A11: =Prices!A12 -> 44945 | B11: =LN(Prices!B12/Prices!B11) -> -0.013416091 | C11: =LN(Prices!C12/Prices!C11) -> -0.025482369 | D11: =LN(Prices!D12/Prices!D11) -> -0.014637963 | E11: =SUMPRODUCT(B11:D11,Inputs!$B$4:$D$4) -> -0.017402536 | F11: =E11*Inputs!$B$2 -> -17402.536
A12: =Prices!A13 -> 44946 | B12: =LN(Prices!B13/Prices!B12) -> 0.0024458691 | C12: =LN(Prices!C13/Prices!C12) -> 0.021955684 | D12: =LN(Prices!D13/Prices!D12) -> 0.018485607 | E12: =SUMPRODUCT(B12:D12,Inputs!$B$4:$D$4) -> 0.013110735 | F12: =E12*Inputs!$B$2 -> 13110.735
A13: =Prices!A14 -> 44949 | B13: =LN(Prices!B14/Prices!B13) -> 0.016082803 | C13: =LN(Prices!C14/Prices!C13) -> 0.00920523 | D13: =LN(Prices!D14/Prices!D13) -> 0.01378958 | E13: =SUMPRODUCT(B13:D13,Inputs!$B$4:$D$4) -> 0.013331564 | F13: =E13*Inputs!$B$2 -> 13331.564
... A501: =Prices!A502 -> 45657 | B501: =LN(Prices!B502/Prices!B501) -> 0.0016283066 | C501: =LN(Prices!C502/Prices!C501) -> -0.00023859482 | D501: =LN(Prices!D502/Prices!D501) -> 0.00091048075 | E501: =SUMPRODUCT(B501:D501,Inputs!$B$4:$D$4) -> 0.00085288843 | F501: =E501*Inputs!$B$2 -> 852.88843

Sheet Parametric
A1: Variance-covariance VaR (latest 250-day window)
A2: Covariance (daily) | B2: JPM | C2: MS | D2: BAC
A3: JPM | B3: =_xlfn.COVARIANCE.S(Returns!B252:B501,Returns!B252:B501) -> 0.00021699414 | C3: =_xlfn.COVARIANCE.S(Returns!B252:B501,Returns!C252:C501) -> 0.00015461865 | D3: =_xlfn.COVARIANCE.S(Returns!B252:B501,Returns!D252:D501) -> 0.00015610232
A4: MS | B4: =_xlfn.COVARIANCE.S(Returns!C252:C501,Returns!B252:B501) -> 0.00015461865 | C4: =_xlfn.COVARIANCE.S(Returns!C252:C501,Returns!C252:C501) -> 0.00026694972 | D4: =_xlfn.COVARIANCE.S(Returns!C252:C501,Returns!D252:D501) -> 0.00015809969
A5: BAC | B5: =_xlfn.COVARIANCE.S(Returns!D252:D501,Returns!B252:B501) -> 0.00015610232 | C5: =_xlfn.COVARIANCE.S(Returns!D252:D501,Returns!C252:C501) -> 0.00015809969 | D5: =_xlfn.COVARIANCE.S(Returns!D252:D501,Returns!D252:D501) -> 0.00020305107
A7: Portfolio variance (w'Sigma w) | B7: =SUMPRODUCT(MMULT(Inputs!B4:D4,B3:D5),Inputs!B4:D4) -> 0.00018005011
A8: Portfolio daily sigma | B8: =SQRT(B7) -> 0.013418275
A10: Confidence | B10: z-score | C10: 1-day VaR (USD) | D10: VaR % of notional
A11: 0.99 | B11: =NORMSINV(A11) -> 2.3263479 | C11: =B11*$B$8*Inputs!$B$2 -> 31215.576 | D11: =C11/Inputs!$B$2 -> 0.031215576
A12: 0.95 | B12: =NORMSINV(A12) -> 1.6448536 | C12: =B12*$B$8*Inputs!$B$2 -> 22071.099 | D12: =C12/Inputs!$B$2 -> 0.022071099
A13: 0.9 | B13: =NORMSINV(A13) -> 1.2815516 | C13: =B13*$B$8*Inputs!$B$2 -> 17196.212 | D13: =C13/Inputs!$B$2 -> 0.017196212

Sheet Historical
A1: Historical simulation VaR (latest 250-day window)
A3: Confidence | B3: Percentile | C3: 1-day VaR (USD) | D3: VaR % of notional
A4: 0.99 | B4: =1-A4 -> 0.01 | C4: =-PERCENTILE(Returns!F252:F501,B4) -> 31363.023 | D4: =C4/Inputs!$B$2 -> 0.031363023
A5: 0.95 | B5: =1-A5 -> 0.05 | C5: =-PERCENTILE(Returns!F252:F501,B5) -> 19926.395 | D5: =C5/Inputs!$B$2 -> 0.019926395
A6: 0.9 | B6: =1-A6 -> 0.1 | C6: =-PERCENTILE(Returns!F252:F501,B6) -> 11828.857 | D6: =C6/Inputs!$B$2 -> 0.011828857
A8: Worst daily P&L in window | C8: =MIN(Returns!F252:F501) -> -50233.362

Sheet MC_Shocks
A1: Fixed standard-normal draws (seed 42) so results are reproducible
A2: 0.49671415 | B2: -0.1382643 | C2: 0.64768854
A3: 1.5230299 | B3: -0.23415337 | C3: -0.23413696
A4: 1.5792128 | B4: 0.76743473 | C4: -0.46947439
A5: 0.54256004 | B5: -0.46341769 | C5: -0.46572975
A6: 0.24196227 | B6: -1.9132802 | C6: -1.7249178
A7: -0.56228753 | B7: -1.0128311 | C7: 0.31424733
A8: -0.90802408 | B8: -1.4123037 | C8: 1.4656488
A9: -0.2257763 | B9: 0.067528205 | C9: -1.4247482
A10: -0.54438272 | B10: 0.11092259 | C10: -1.1509936
A11: 0.37569802 | B11: -0.60063869 | C11: -0.29169375
A12: -0.60170661 | B12: 1.8522782 | C12: -0.013497225
A13: -1.0577109 | B13: 0.82254491 | C13: -1.2208436
... A1001: -1.2417606 | B1001: 0.33417642 | C1001: -0.15525905

Sheet MonteCarlo
A1: Monte Carlo VaR: Cholesky of the Parametric covariance matrix, 1,000 simulated days
A2: Cholesky L (rows: assets, lower triangular)
A3: JPM | B3: =SQRT(Parametric!B3) -> 0.014730721
A4: MS | B4: =Parametric!B4/B3 -> 0.010496339 | C4: =SQRT(Parametric!C4-B4^2) -> 0.012521045
A5: BAC | B5: =Parametric!B5/B3 -> 0.010597059 | C5: =(Parametric!C5-B5*B4)/C4 -> 0.0037432469 | D5: =SQRT(Parametric!D5-B5^2-C5^2) -> 0.0087602235
A7: Confidence | B7: 1-day VaR (USD) | C7: VaR % of notional
A8: 0.99 | B8: =-PERCENTILE($J$15:$J$1014,1-A8) -> 29875.331 | C8: =B8/Inputs!$B$2 -> 0.029875331
A9: 0.95 | B9: =-PERCENTILE($J$15:$J$1014,1-A9) -> 19594.881 | C9: =B9/Inputs!$B$2 -> 0.019594881
A10: 0.9 | B10: =-PERCENTILE($J$15:$J$1014,1-A10) -> 15355.635 | C10: =B10/Inputs!$B$2 -> 0.015355635
D14: z1 | E14: z2 | F14: z3 | G14: ret1 | H14: ret2 | I14: ret3 | J14: Portfolio P&L (USD)
D15: =MC_Shocks!A2 -> 0.49671415 | E15: =MC_Shocks!B2 -> -0.1382643 | F15: =MC_Shocks!C2 -> 0.64768854 | G15: =$B$3*D15 -> 0.0073169576 | H15: =$B$4*D15+$C$4*E15 -> 0.0034824668 | I15: =$B$5*D15+$C$5*E15+$D$5*F15 -> 0.010420048 | J15: =SUMPRODUCT(G15:I15,Inputs!$B$4:$D$4)*Inputs!$B$2 -> 7097.5375
D16: =MC_Shocks!A3 -> 1.5230299 | E16: =MC_Shocks!B3 -> -0.23415337 | F16: =MC_Shocks!C3 -> -0.23413696 | G16: =$B$3*D16 -> 0.022435328 | H16: =$B$4*D16+$C$4*E16 -> 0.013054393 | I16: =$B$5*D16+$C$5*E16+$D$5*F16 -> 0.013212051 | J16: =SUMPRODUCT(G16:I16,Inputs!$B$4:$D$4)*Inputs!$B$2 -> 16854.064
D17: =MC_Shocks!A4 -> 1.5792128 | E17: =MC_Shocks!B4 -> 0.76743473 | F17: =MC_Shocks!C4 -> -0.46947439 | G17: =$B$3*D17 -> 0.023262943 | H17: =$B$4*D17+$C$4*E17 -> 0.026185039 | I17: =$B$5*D17+$C$5*E17+$D$5*F17 -> 0.015495008 | J17: =SUMPRODUCT(G17:I17,Inputs!$B$4:$D$4)*Inputs!$B$2 -> 21809.191
D18: =MC_Shocks!A5 -> 0.54256004 | E18: =MC_Shocks!B5 -> -0.46341769 | F18: =MC_Shocks!C5 -> -0.46572975 | G18: =$B$3*D18 -> 0.0079923006 | H18: =$B$4*D18+$C$4*E18 -> -0.00010757957 | I18: =$B$5*D18+$C$5*E18+$D$5*F18 -> -6.5042888e-05 | J18: =SUMPRODUCT(G18:I18,Inputs!$B$4:$D$4)*Inputs!$B$2 -> 3145.1335
D19: =MC_Shocks!A6 -> 0.24196227 | E19: =MC_Shocks!B6 -> -1.9132802 | F19: =MC_Shocks!C6 -> -1.7249178 | G19: =$B$3*D19 -> 0.0035642787 | H19: =$B$4*D19+$C$4*E19 -> -0.021416551 | I19: =$B$5*D19+$C$5*E19+$D$5*F19 -> -0.019708458 | J19: =SUMPRODUCT(G19:I19,Inputs!$B$4:$D$4)*Inputs!$B$2 -> -10911.791
D20: =MC_Shocks!A7 -> -0.56228753 | E20: =MC_Shocks!B7 -> -1.0128311 | F20: =MC_Shocks!C7 -> 0.31424733 | G20: =$B$3*D20 -> -0.0082829007 | H20: =$B$4*D20+$C$4*E20 -> -0.018583665 | I20: =$B$5*D20+$C$5*E20+$D$5*F20 -> -0.0069969941 | J20: =SUMPRODUCT(G20:I20,Inputs!$B$4:$D$4)*Inputs!$B$2 -> -10987.358
D21: =MC_Shocks!A8 -> -0.90802408 | E21: =MC_Shocks!B8 -> -1.4123037 | F21: =MC_Shocks!C8 -> 1.4656488 | G21: =$B$3*D21 -> -0.013375849 | H21: =$B$4*D21+$C$4*E21 -> -0.027214448 | I21: =$B$5*D21+$C$5*E21+$D$5*F21 -> -0.0020695752 | J21: =SUMPRODUCT(G21:I21,Inputs!$B$4:$D$4)*Inputs!$B$2 -> -14135.547
D22: =MC_Shocks!A9 -> -0.2257763 | E22: =MC_Shocks!B9 -> 0.067528205 | F22: =MC_Shocks!C9 -> -1.4247482 | G22: =$B$3*D22 -> -0.0033258477 | H22: =$B$4*D22+$C$4*E22 -> -0.001524301 | I22: =$B$5*D22+$C$5*E22+$D$5*F22 -> -0.014620903 | J22: =SUMPRODUCT(G22:I22,Inputs!$B$4:$D$4)*Inputs!$B$2 -> -6173.9001
D23: =MC_Shocks!A10 -> -0.54438272 | E23: =MC_Shocks!B10 -> 0.11092259 | F23: =MC_Shocks!C10 -> -1.1509936 | G23: =$B$3*D23 -> -0.00801915 | H23: =$B$4*D23+$C$4*E23 -> -0.0043251591 | I23: =$B$5*D23+$C$5*E23+$D$5*F23 -> -0.015436606 | J23: =SUMPRODUCT(G23:I23,Inputs!$B$4:$D$4)*Inputs!$B$2 -> -9136.1896
D24: =MC_Shocks!A11 -> 0.37569802 | E24: =MC_Shocks!B11 -> -0.60063869 | F24: =MC_Shocks!C11 -> -0.29169375 | G24: =$B$3*D24 -> 0.0055343027 | H24: =$B$4*D24+$C$4*E24 -> -0.0035771703 | I24: =$B$5*D24+$C$5*E24+$D$5*F24 -> -0.00082234736 | J24: =SUMPRODUCT(G24:I24,Inputs!$B$4:$D$4)*Inputs!$B$2 -> 893.86576
D25: =MC_Shocks!A12 -> -0.60170661 | E25: =MC_Shocks!B12 -> 1.8522782 | F25: =MC_Shocks!C12 -> -0.013497225 | G25: =$B$3*D25 -> -0.0088635722 | H25: =$B$4*D25+$C$4*E25 -> 0.016876742 | I25: =$B$5*D25+$C$5*E25+$D$5*F25 -> 0.00043897551 | J25: =SUMPRODUCT(G25:I25,Inputs!$B$4:$D$4)*Inputs!$B$2 -> 1649.2865
D26: =MC_Shocks!A13 -> -1.0577109 | E26: =MC_Shocks!B13 -> 0.82254491 | F26: =MC_Shocks!C13 -> -1.2208436 | G26: =$B$3*D26 -> -0.015580845 | H26: =$B$4*D26+$C$4*E26 -> -0.00080297078 | I26: =$B$5*D26+$C$5*E26+$D$5*F26 -> -0.018824499 | J26: =SUMPRODUCT(G26:I26,Inputs!$B$4:$D$4)*Inputs!$B$2 -> -12120.579
... D1014: =MC_Shocks!A1001 -> -1.2417606 | E1014: =MC_Shocks!B1001 -> 0.33417642 | F1014: =MC_Shocks!C1001 -> -0.15525905 | G1014: =$B$3*D1014 -> -0.018292029 | H1014: =$B$4*D1014+$C$4*E1014 -> -0.0088497024 | I1014: =$B$5*D1014+$C$5*E1014+$D$5*F1014 -> -0.013268209 | J1014: =SUMPRODUCT(G1014:I1014,Inputs!$B$4:$D$4)*Inputs!$B$2 -> -13952.185

Sheet Backtest
A1: Rolling 250-day backtest at 99%: 250 out-of-sample days. VaR for day t uses the 250 returns before t.
A3: Date | B3: Actual loss (USD) | C3: Historical VaR 99% | D3: Parametric VaR 99% | E3: HS exception | F3: Param exception | H3: Test | I3: Historical | J3: Parametric
A4: =Returns!A252 -> 45295 | B4: =-Returns!F252 -> -5834.1424 | C4: =-PERCENTILE(Returns!$F$2:$F$251,0.01) -> 35195.7 | D4: =NORMSINV(0.99)*STDEV(Returns!$F$2:$F$251) -> 31258.965 | E4: =IF(B4>C4,1,0) -> 0 | F4: =IF(B4>D4,1,0) -> 0 | H4: Observations n | I4: =COUNT(B4:B253) -> 250 | J4: =COUNT(B4:B253) -> 250
A5: =Returns!A253 -> 45296 | B5: =-Returns!F253 -> -11069.817 | C5: =-PERCENTILE(Returns!$F$3:$F$252,0.01) -> 35195.7 | D5: =NORMSINV(0.99)*STDEV(Returns!$F$3:$F$252) -> 31263.598 | E5: =IF(B5>C5,1,0) -> 0 | F5: =IF(B5>D5,1,0) -> 0 | H5: Exceptions x | I5: =SUM(E4:E253) -> 4 | J5: =SUM(F4:F253) -> 4
A6: =Returns!A254 -> 45299 | B6: =-Returns!F254 -> 2075.3149 | C6: =-PERCENTILE(Returns!$F$4:$F$253,0.01) -> 35195.7 | D6: =NORMSINV(0.99)*STDEV(Returns!$F$4:$F$253) -> 31216.605 | E6: =IF(B6>C6,1,0) -> 0 | F6: =IF(B6>D6,1,0) -> 0 | H6: Expected exceptions n*p | I6: =I4*0.01 -> 2.5 | J6: =J4*0.01 -> 2.5
A7: =Returns!A255 -> 45300 | B7: =-Returns!F255 -> 12554.343 | C7: =-PERCENTILE(Returns!$F$5:$F$254,0.01) -> 35195.7 | D7: =NORMSINV(0.99)*STDEV(Returns!$F$5:$F$254) -> 31204.246 | E7: =IF(B7>C7,1,0) -> 0 | F7: =IF(B7>D7,1,0) -> 0 | H7: Kupiec POF LR statistic | I7: =IF(I5=0,-2*I4*LN(0.99),-2*((I4-I5)*LN(0.99)+I5*LN(0.01)-((I4-I5)*LN(1-I5/I4)+I5*LN(I5/I4)))) -> 0.76913836 | J7: =IF(J5=0,-2*J4*LN(0.99),-2*((J4-J5)*LN(0.99)+J5*LN(0.01)-((J4-J5)*LN(1-J5/J4)+J5*LN(J5/J4)))) -> 0.76913836
A8: =Returns!A256 -> 45301 | B8: =-Returns!F256 -> 1320.912 | C8: =-PERCENTILE(Returns!$F$6:$F$255,0.01) -> 35195.7 | D8: =NORMSINV(0.99)*STDEV(Returns!$F$6:$F$255) -> 31232.981 | E8: =IF(B8>C8,1,0) -> 0 | F8: =IF(B8>D8,1,0) -> 0 | H8: Chi-square critical (5%, 1 df) | I8: =CHIINV(0.05,1) -> 3.8414588 | J8: =CHIINV(0.05,1) -> 3.8414588
A9: =Returns!A257 -> 45302 | B9: =-Returns!F257 -> 8930.5741 | C9: =-PERCENTILE(Returns!$F$7:$F$256,0.01) -> 35195.7 | D9: =NORMSINV(0.99)*STDEV(Returns!$F$7:$F$256) -> 31219.452 | E9: =IF(B9>C9,1,0) -> 0 | F9: =IF(B9>D9,1,0) -> 0 | H9: Kupiec result | I9: =IF(I7>I8,"Reject model","Do not reject") -> Do not reject | J9: =IF(J7>J8,"Reject model","Do not reject") -> Do not reject
A10: =Returns!A258 -> 45303 | B10: =-Returns!F258 -> 8828.0372 | C10: =-PERCENTILE(Returns!$F$8:$F$257,0.01) -> 35195.7 | D10: =NORMSINV(0.99)*STDEV(Returns!$F$8:$F$257) -> 31245.339 | E10: =IF(B10>C10,1,0) -> 0 | F10: =IF(B10>D10,1,0) -> 0 | H10: Basel traffic light (250 days) | I10: =IF(I5<=4,"Green",IF(I5<=9,"Yellow","Red")) -> Green | J10: =IF(J5<=4,"Green",IF(J5<=9,"Yellow","Red")) -> Green
A11: =Returns!A259 -> 45307 | B11: =-Returns!F259 -> 21542.662 | C11: =-PERCENTILE(Returns!$F$9:$F$258,0.01) -> 35195.7 | D11: =NORMSINV(0.99)*STDEV(Returns!$F$9:$F$258) -> 31136.782 | E11: =IF(B11>C11,1,0) -> 0 | F11: =IF(B11>D11,1,0) -> 0
A12: =Returns!A260 -> 45308 | B12: =-Returns!F260 -> 10646.153 | C12: =-PERCENTILE(Returns!$F$10:$F$259,0.01) -> 35195.7 | D12: =NORMSINV(0.99)*STDEV(Returns!$F$10:$F$259) -> 31294.241 | E12: =IF(B12>C12,1,0) -> 0 | F12: =IF(B12>D12,1,0) -> 0
A13: =Returns!A261 -> 45309 | B13: =-Returns!F261 -> 1689.9962 | C13: =-PERCENTILE(Returns!$F$11:$F$260,0.01) -> 35195.7 | D13: =NORMSINV(0.99)*STDEV(Returns!$F$11:$F$260) -> 31181.984 | E13: =IF(B13>C13,1,0) -> 0 | F13: =IF(B13>D13,1,0) -> 0
A14: =Returns!A262 -> 45310 | B14: =-Returns!F262 -> -16548.483 | C14: =-PERCENTILE(Returns!$F$12:$F$261,0.01) -> 35195.7 | D14: =NORMSINV(0.99)*STDEV(Returns!$F$12:$F$261) -> 31074.515 | E14: =IF(B14>C14,1,0) -> 0 | F14: =IF(B14>D14,1,0) -> 0
A15: =Returns!A263 -> 45313 | B15: =-Returns!F263 -> -3954.8668 | C15: =-PERCENTILE(Returns!$F$13:$F$262,0.01) -> 35195.7 | D15: =NORMSINV(0.99)*STDEV(Returns!$F$13:$F$262) -> 31109.46 | E15: =IF(B15>C15,1,0) -> 0 | F15: =IF(B15>D15,1,0) -> 0
A16: =Returns!A264 -> 45314 | B16: =-Returns!F264 -> -2892.3605 | C16: =-PERCENTILE(Returns!$F$14:$F$263,0.01) -> 35195.7 | D16: =NORMSINV(0.99)*STDEV(Returns!$F$14:$F$263) -> 31054.599 | E16: =IF(B16>C16,1,0) -> 0 | F16: =IF(B16>D16,1,0) -> 0
A17: =Returns!A265 -> 45315 | B17: =-Returns!F265 -> -8331.6909 | C17: =-PERCENTILE(Returns!$F$15:$F$264,0.01) -> 35195.7 | D17: =NORMSINV(0.99)*STDEV(Returns!$F$15:$F$264) -> 31056.99 | E17: =IF(B17>C17,1,0) -> 0 | F17: =IF(B17>D17,1,0) -> 0
A18: =Returns!A266 -> 45316 | B18: =-Returns!F266 -> -10927.939 | C18: =-PERCENTILE(Returns!$F$16:$F$265,0.01) -> 35195.7 | D18: =NORMSINV(0.99)*STDEV(Returns!$F$16:$F$265) -> 31072.116 | E18: =IF(B18>C18,1,0) -> 0 | F18: =IF(B18>D18,1,0) -> 0
A19: =Returns!A267 -> 45317 | B19: =-Returns!F267 -> 2160.3439 | C19: =-PERCENTILE(Returns!$F$17:$F$266,0.01) -> 35195.7 | D19: =NORMSINV(0.99)*STDEV(Returns!$F$17:$F$266) -> 31084.139 | E19: =IF(B19>C19,1,0) -> 0 | F19: =IF(B19>D19,1,0) -> 0
A20: =Returns!A268 -> 45320 | B20: =-Returns!F268 -> -2277.9946 | C20: =-PERCENTILE(Returns!$F$18:$F$267,0.01) -> 35195.7 | D20: =NORMSINV(0.99)*STDEV(Returns!$F$18:$F$267) -> 31083.585 | E20: =IF(B20>C20,1,0) -> 0 | F20: =IF(B20>D20,1,0) -> 0
A21: =Returns!A269 -> 45321 | B21: =-Returns!F269 -> -21391.309 | C21: =-PERCENTILE(Returns!$F$19:$F$268,0.01) -> 35195.7 | D21: =NORMSINV(0.99)*STDEV(Returns!$F$19:$F$268) -> 31074.969 | E21: =IF(B21>C21,1,0) -> 0 | F21: =IF(B21>D21,1,0) -> 0
A22: =Returns!A270 -> 45322 | B22: =-Returns!F270 -> 12464.443 | C22: =-PERCENTILE(Returns!$F$20:$F$269,0.01) -> 35195.7 | D22: =NORMSINV(0.99)*STDEV(Returns!$F$20:$F$269) -> 31208.447 | E22: =IF(B22>C22,1,0) -> 0 | F22: =IF(B22>D22,1,0) -> 0
A23: =Returns!A271 -> 45323 | B23: =-Returns!F271 -> 6980.969 | C23: =-PERCENTILE(Returns!$F$21:$F$270,0.01) -> 35195.7 | D23: =NORMSINV(0.99)*STDEV(Returns!$F$21:$F$270) -> 31256.683 | E23: =IF(B23>C23,1,0) -> 0 | F23: =IF(B23>D23,1,0) -> 0
A24: =Returns!A272 -> 45324 | B24: =-Returns!F272 -> -3130.5258 | C24: =-PERCENTILE(Returns!$F$22:$F$271,0.01) -> 35195.7 | D24: =NORMSINV(0.99)*STDEV(Returns!$F$22:$F$271) -> 31272.318 | E24: =IF(B24>C24,1,0) -> 0 | F24: =IF(B24>D24,1,0) -> 0
A25: =Returns!A273 -> 45327 | B25: =-Returns!F273 -> 9642.1011 | C25: =-PERCENTILE(Returns!$F$23:$F$272,0.01) -> 35195.7 | D25: =NORMSINV(0.99)*STDEV(Returns!$F$23:$F$272) -> 31246.704 | E25: =IF(B25>C25,1,0) -> 0 | F25: =IF(B25>D25,1,0) -> 0
A26: =Returns!A274 -> 45328 | B26: =-Returns!F274 -> -2559.808 | C26: =-PERCENTILE(Returns!$F$24:$F$273,0.01) -> 35195.7 | D26: =NORMSINV(0.99)*STDEV(Returns!$F$24:$F$273) -> 31280.331 | E26: =IF(B26>C26,1,0) -> 0 | F26: =IF(B26>D26,1,0) -> 0
A27: =Returns!A275 -> 45329 | B27: =-Returns!F275 -> -1673.0281 | C27: =-PERCENTILE(Returns!$F$25:$F$274,0.01) -> 35195.7 | D27: =NORMSINV(0.99)*STDEV(Returns!$F$25:$F$274) -> 31254.576 | E27: =IF(B27>C27,1,0) -> 0 | F27: =IF(B27>D27,1,0) -> 0
A28: =Returns!A276 -> 45330 | B28: =-Returns!F276 -> 3205.4129 | C28: =-PERCENTILE(Returns!$F$26:$F$275,0.01) -> 35195.7 | D28: =NORMSINV(0.99)*STDEV(Returns!$F$26:$F$275) -> 31242.92 | E28: =IF(B28>C28,1,0) -> 0 | F28: =IF(B28>D28,1,0) -> 0
A29: =Returns!A277 -> 45331 | B29: =-Returns!F277 -> -866.40576 | C29: =-PERCENTILE(Returns!$F$27:$F$276,0.01) -> 35195.7 | D29: =NORMSINV(0.99)*STDEV(Returns!$F$27:$F$276) -> 31160.802 | E29: =IF(B29>C29,1,0) -> 0 | F29: =IF(B29>D29,1,0) -> 0
A30: =Returns!A278 -> 45334 | B30: =-Returns!F278 -> -10130.814 | C30: =-PERCENTILE(Returns!$F$28:$F$277,0.01) -> 35195.7 | D30: =NORMSINV(0.99)*STDEV(Returns!$F$28:$F$277) -> 31160.108 | E30: =IF(B30>C30,1,0) -> 0 | F30: =IF(B30>D30,1,0) -> 0
A31: =Returns!A279 -> 45335 | B31: =-Returns!F279 -> 21548.064 | C31: =-PERCENTILE(Returns!$F$29:$F$278,0.01) -> 35195.7 | D31: =NORMSINV(0.99)*STDEV(Returns!$F$29:$F$278) -> 31173.739 | E31: =IF(B31>C31,1,0) -> 0 | F31: =IF(B31>D31,1,0) -> 0
A32: =Returns!A280 -> 45336 | B32: =-Returns!F280 -> -7610.3758 | C32: =-PERCENTILE(Returns!$F$30:$F$279,0.01) -> 35195.7 | D32: =NORMSINV(0.99)*STDEV(Returns!$F$30:$F$279) -> 31330.142 | E32: =IF(B32>C32,1,0) -> 0 | F32: =IF(B32>D32,1,0) -> 0
A33: =Returns!A281 -> 45337 | B33: =-Returns!F281 -> -22931.264 | C33: =-PERCENTILE(Returns!$F$31:$F$280,0.01) -> 35195.7 | D33: =NORMSINV(0.99)*STDEV(Returns!$F$31:$F$280) -> 31348.34 | E33: =IF(B33>C33,1,0) -> 0 | F33: =IF(B33>D33,1,0) -> 0
A34: =Returns!A282 -> 45338 | B34: =-Returns!F282 -> -1196.111 | C34: =-PERCENTILE(Returns!$F$32:$F$281,0.01) -> 35195.7 | D34: =NORMSINV(0.99)*STDEV(Returns!$F$32:$F$281) -> 31477.75 | E34: =IF(B34>C34,1,0) -> 0 | F34: =IF(B34>D34,1,0) -> 0
A35: =Returns!A283 -> 45342 | B35: =-Returns!F283 -> 3600.506 | C35: =-PERCENTILE(Returns!$F$33:$F$282,0.01) -> 35195.7 | D35: =NORMSINV(0.99)*STDEV(Returns!$F$33:$F$282) -> 31477.444 | E35: =IF(B35>C35,1,0) -> 0 | F35: =IF(B35>D35,1,0) -> 0
A36: =Returns!A284 -> 45343 | B36: =-Returns!F284 -> -676.28764 | C36: =-PERCENTILE(Returns!$F$34:$F$283,0.01) -> 35195.7 | D36: =NORMSINV(0.99)*STDEV(Returns!$F$34:$F$283) -> 31335.817 | E36: =IF(B36>C36,1,0) -> 0 | F36: =IF(B36>D36,1,0) -> 0
A37: =Returns!A285 -> 45344 | B37: =-Returns!F285 -> -5333.3223 | C37: =-PERCENTILE(Returns!$F$35:$F$284,0.01) -> 35195.7 | D37: =NORMSINV(0.99)*STDEV(Returns!$F$35:$F$284) -> 31321.074 | E37: =IF(B37>C37,1,0) -> 0 | F37: =IF(B37>D37,1,0) -> 0
A38: =Returns!A286 -> 45345 | B38: =-Returns!F286 -> -7195.7406 | C38: =-PERCENTILE(Returns!$F$36:$F$285,0.01) -> 35195.7 | D38: =NORMSINV(0.99)*STDEV(Returns!$F$36:$F$285) -> 31322.219 | E38: =IF(B38>C38,1,0) -> 0 | F38: =IF(B38>D38,1,0) -> 0
A39: =Returns!A287 -> 45348 | B39: =-Returns!F287 -> 7192.2162 | C39: =-PERCENTILE(Returns!$F$37:$F$286,0.01) -> 35195.7 | D39: =NORMSINV(0.99)*STDEV(Returns!$F$37:$F$286) -> 31336.855 | E39: =IF(B39>C39,1,0) -> 0 | F39: =IF(B39>D39,1,0) -> 0
A40: =Returns!A288 -> 45349 | B40: =-Returns!F288 -> -5486.7332 | C40: =-PERCENTILE(Returns!$F$38:$F$287,0.01) -> 35195.7 | D40: =NORMSINV(0.99)*STDEV(Returns!$F$38:$F$287) -> 31356.761 | E40: =IF(B40>C40,1,0) -> 0 | F40: =IF(B40>D40,1,0) -> 0
A41: =Returns!A289 -> 45350 | B41: =-Returns!F289 -> -4243.9358 | C41: =-PERCENTILE(Returns!$F$39:$F$288,0.01) -> 35195.7 | D41: =NORMSINV(0.99)*STDEV(Returns!$F$39:$F$288) -> 31362.43 | E41: =IF(B41>C41,1,0) -> 0 | F41: =IF(B41>D41,1,0) -> 0
...
